Workbook

Sheet Company Info
A1: HealthySure Template
A2: Basic Company Details
A4: Brand Name of the Company | B4: ABC
A5: Legal Name of the Company | B5: ABC Pvt Ltd
A6: Address of the Company
A7: Pincode of the Company
A8: Contact Person - Name | B8: Pending
A9: Contact Person - Mobile No | B9: Pending
A10: Contact Person - Email ID | B10: Pending
A11: GST or PAN of Company
A12: Nature of Industry

Sheet Expiring Policy Terms
B7: Expiring Policy Terms
B10: Insured Name | C10: : | D10: WRITER BUSINESS SERVICES PRIVATE LIMITED
B11: Address | C11: : | D11: Mumbai
B12: Existing Insurer | C12: : | D12: Iffco
B13: Existing TPA | C13: : | D13: Paramount
B14: Policy Period | C14: : | D14: 27/07/2020 - 26/07/2021
B16: Scope of Coverage: | C16: : | D16: Expiring
B17: Family Definition | C17: : | D17: Self + Spouse + 2 Dependent Children (upto the age of 23 years) + 2 Dependent Parents (upto the age of 80 years).
B18: Coverage of Dependent's till policy expiry in case of death of the employee | D18: Not Covered
B19: Sum Insured | C19: : | D19: Rs. 200,000, Rs. 300,000,Rs,500000
B20: Domiciliary hospitalization expenses | C20: : | D20: Not Covered
B21: Pre-existing Diseases Coverage | C21: : | D21: Covered from Day One
B22: First 30 days and 1st and 2nd & 4th year waiting period | C22: : | D22: Waived off
B23: Maternity cover | C23: : | D23: Not Covered
B24: 9 months waiting period for Maternity cover | C24: : | D24: Not Applicable
B25: Room rent | C25: : | D25: 1.5% of SI for normal and 2.5% of SI for ICU/ICCU, all other charges accordance with the room rent restriction. In case if the insured opts for a higher room rent than his eligibility, the proporationate increase in the cost of room rent and other incidental charges will have to be borne by the employee
B26: Pre & Post hospitalization expenses covered for 30 & 60 days respectively | C26: : | D26: Covered
B27: Pre post natal Cover | C27: : | D27: Not Applicable
B28: Baby covered | C28: : | D28: New born baby covered from day one
B29: Day care surgeries | C29: : | D29: Covered
B30: Ambulance Charges | C30: : | D30: covered upto Rs. 1,000/- per incident in case of emergency.
... B34: Corporate Buffer | C34: : | D34: Corporate Buffer for 1 Crore with restricted to INR 500,00 for all Ailments except Maternity
B35: Organ Donor Expenses | D35: In case of an organ transplant, if there is a need of an organ donor, hospitalisation charges for the organ donor should be covered excl. Organ cost
B36: Psychiatric treatment | D36: covered only for Employees on IPD Basis
B37: Bereavement Cover | D37: 100% of the claimed amount is paid if the claimant passes away during hospitalization cover
B38: Mid term Increase in Sum Insured | C38: : | D38: not allowed except due to promotion to higher cadre.
B39: Mid-term Addition of Dependents | C39: : | D39: only in case of new born baby and spouse in case of marriage.
B40: Mid-term addition of parents | C40: : | D40: not allowed except for new joinees.
B41: Addition/Deletion | C41: : | D41: Addition/Deletion on prorata basis from Date of Joining and Date of Leaving respectively subject to CD balance.
B42: Refund of premium on account of Mid-term Deletion of member | C42: : | D42: allowed from the date of resignation subject to receipt of intimation within 45 days from the date of resignation failing which refund will be calculated from the date of intimation to the Company. No refund for deletion if employee or family member has claimed during the Policy
B43: Claim Intimation | C43: : | D43: waived off
B44: Claim document submission | C44: : | D44: within 45 days from date of discharge
B45: Portability | C45: :

Sheet GHI RFQ
A1: HEALTHYSURE
A2: Insured Name | B2: ='Company Info'!B5 -> ABC Pvt Ltd
A3: Policy Type | B3: Group Mediclaim Cover
A4: Case Type | B4: Renewal
A5: Policy Expiry Date
A6: Previous Year Insurer
A7: Previous Year TPA
A8: Previous Year Broker
A9: CLAIMS INFORMATION
B10: 2023-24 | C10: 2024-25 | D10: 2025-26
A11: Premium at Inception | B11: Not Available | C11: Not Available | D11: 300000
A12: Premium at Expiry | B12: Not Available | C12: Not Available | D12: 500000
A13: Claims (Paid + Outstanding) | B13: Not Available | C13: Not Available | D13: ='Renewal Quote Predict'!C14 -> 370000
A14: Annualised claims | B14: Not Available | C14: Not Available | D14: ='Renewal Quote Predict'!C18 -> 432160
A15: Loss Ratio on annualised claims | B15: =B14/B12 -> #VALUE! | C15: =C14/C12 -> #VALUE! | D15: =D14/D12 -> 0.86432
A16: Claims Per Life | B16: =B14/(B19*B12/B11) -> #VALUE! | C16: =C14/(C19*C12/C11) -> #VALUE! | D16: =D14/(D19*D12/D11) -> 2592.96
A17: Claims MIS Date | B17: Not Available | C17: Not Available | D17: ='Renewal Quote Predict'!C5 -> 46077
A18: Insurer | D18: =B6 -> 0
A19: Inception NOL | D19: =B27 -> 100
A20: Expiring NOL | D20: =C27 -> 200
A21: EMPLOYEE COUNT
B22: At Inception (2025-26) | C22: At Expiry (2025-26) | D22: For Renewal (2026-27)
A23: Total Employees | B23: 100 | C23: 200 | D23: 200
A24: Total Spouse
A25: Total Children
A26: Total Parents/Parents-in-law
A27: Total Members | B27: =SUM(B23:B26) -> 100 | C27: =SUM(C23:C26) -> 200 | D27: =SUM(D23:D26) -> 200
A28: Reason for Increase/Decrease in Demography | B28: Company is in growth phase / mass-hiring etc
A29: GMC COVERAGE
A30: Policy Features | B30: Previous Year | D30: Current Year
A31: Family Definition | B31: Self , Spouse, 4 Children upto 25 yrs & 2 Parents/Parent- in-law upto 80 yrs | D31: Same
A32: Sum Insured | B32: Rs. X lacs | D32: Same
A33: Policy Type | B33: Family Floater | D33: Same
A34: Rater Type | B34: Age Bandwise Rates per life/ Flat Rate per life | D34: Same
A35: Co-Pay | B35: 0% for All | D35: Same
A36: Parental Co-Pay | B36: 0% for All | D36: Same
A37: Room Rent Restriction | B37: Normal - 2% of SI per day ICU - 4% of SI per day | D37: Same
A38: Room Rent Proportionate Clause | B38: Applicable | D38: Same
A39: Corporate Buffer | B39: Rs. XXX restricted to Family Floater SI <for all ailments/ critical illness> | D39: Same
A40: Hospitals Covered | B40: All Hospitals | D40: Same
...

Sheet Employee_Data
L1: Number of errors: | M1: =COUNT(Table1[S.No.])-COUNTBLANK(Table1[Error]) -> 9
A2: S.No. | B2: Employee ID | C2: Employment Type (On-Roll/Off-Roll) | D2: Member Name | E2: Date of Birth | F2: Age | G2: Age Band | H2: Gender | I2: Relationship to Self | J2: GHI Sum Insured | K2: Mobile Number | L2: Email | M2: Error | N2: Error_Relationship | O2: Error_Age | P2: Error_Gender | Q2: Error_Ph | R2: Error_Email | S2: Error_Name | T2: Error_DoB | U2: Error_Duplicate | V2: Error_EmployeeID | W2: Other Errors, if any
A3: =ROW()-2 -> 1 | F3: =DATEDIF(E3,TODAY(),"y") -> 126 | G3: =IF( $F3>85, "From 86", IF( $F3>80, "81-85", IF( $F3>75, "76-80", IF( $F3>70, "71-75", IF( $F3>65, "66-70", IF( $F3>60, "61-65", IF( $F3>55, "56-60", IF( $F3>50, "51-55", IF( $F3>45, "46-50", IF( $F3>40, "41-45", IF( $F3>35, "36-40", IF( $F3>30, "31-35", IF($F3>25, "26-30", IF($F3>18,"19-25","0-18") ) ) ) ) ) ) ) ) ) ) ) ) ) -> From 86 | M3: =Table1[[#This Row],[Error_Name]] &Table1[[#This Row],[Error_DoB]] &Table1[[#This Row],[Error_Age]] &Table1[[#This Row],[Error_Gender]] &Table1[[#This Row],[Error_Relationship]] &Table1[[#This Row],[Error_Ph]] &Table1[[#This Row],[Error_Email]] &Table1[[#This Row],[Error_Duplicate]] &Table1[[#This Row],[Error_EmployeeID]] -> Please enter Member Name. Invalid gender. Invalid relationship to employee. | N3: =IF(ISNUMBER(MATCH(Table1[[#This Row],[Relationship to Self]],[1]!Table4[Valid Relations],0)),"","Invalid relationship to employee. ") -> Invalid relationship to employee. | O3: =IF( Table1[[#This Row],[Relationship to Self]]=[1]Valid!$C$6, IF(AND(Table1[[#This Row],[Age]]>=[1]Valid!$D$6,Table1[[#This Row],[Age]]<=[1]Valid!$E$6),"",[1]Valid!$C$6 & " age should be between " & [1]Valid!$D$6 & " and " & [1]Valid!$E$6 & ". "), IF( Table1[[#This Row],[Relationship to Self]]=[1]Valid!$C$2, IF(AND(Table1[[#This Row],[Age]]>=[1]Valid!$D$2,Table1[[#This Row],[Age]]<=[1]Valid!$E$2),"",[1]Valid!$C$2 & " age should be between " & [1]Valid!$D$2 & " and " & [1]Valid!$E$2 & ". "), IF( Table1[[#This Row],[Relationship to Self]]=[1]Valid!$C$3, IF(AND(Table1[[#This Row],[Age]]>=[1]Valid!$D$3,Table1[[#This Row],[Age]]<=[1]Valid!$E$3),"",[1]Valid!$C$3 & " age should be between " & [1]Valid!$D$3 & " and " & [1]Valid!$E$3 & ". "), IF( Table1[[#This Row],[Relationship to Self]]=[1]Valid!$C$4, IF(AND(Table1[[#This Row],[Age]]>=[1]Valid!$D$4,Table1[[#This Row],[Age]]<=[1]Valid!$E$4),"",[1]Valid!$C$4 & " age should be between " & [1]Valid!$D$4 & " and " & [1]Valid!$E$4 & ". "), IF( Table1[[#This Row],[Relationship to Self]]=[1]Valid!$C$5, IF(AND(Table1[[#This Row],[Age]]>=[1]Valid!$D$5,Table1[[#This Row],[Age]]<=[1]Valid!$E$5),"",[1]Valid!$C$5 & " age should be between " & [1]Valid!$D$5 & " and " & [1]Valid!$E$5 & ". "), "" ) ) ) ) ) | P3: =IF(ISNUMBER(MATCH(Table1[[#This Row],[Gender]],[1]!Table6[Gender],0)),"","Invalid gender. ") -> Invalid gender. | Q3: =IF(Table1[[#This Row],[Relationship to Self]]<>"Self","",IF(AND(Table1[[#This Row],[Mobile Number]]>6000000000,Table1[[#This Row],[Mobile Number]]<9999999999),"","The entered mobile number is invalid. ")) | R3: {=IF(Table1[[#This Row],[Relationship to Self]]<>"Self","",IF(IsEmailValid(Table1[[#This Row],[Email]]),IF(ISNUMBER(SEARCH([1]Valid!$K$1,Table1[[#This Row],[Email]])),"","The entered email is not corporate email. "),"The entered email is invalid. "))} | S3: =IF(Table1[[#This Row],[Member Name]]="","Please enter Member Name. ","") -> Please enter Member Name. | T3: =IF(YEAR(Table1[[#This Row],[Date of Birth]])=1905, "DoB is incomplete. ","") | U3: =IF(COUNTIFS(Table1[Employee ID],Table1[[#This Row],[Employee ID]],Table1[Date of Birth],Table1[[#This Row],[Date of Birth]],Table1[Relationship to Self],Table1[[#This Row],[Relationship to Self]],Table1[Member Name],Table1[[#This Row],[Member Name]])>1,"This entry is repeated multiple times. ","") | V3: =IF(COUNTIFS(Table1[Employee ID],Table1[[#This Row],[Employee ID]],Table1[Relationship to Self],"Self")>1, "Duplicate Employee ID","")
A4: =ROW()-2 -> 2 | F4: =DATEDIF(E4,TODAY(),"y") -> 126 | G4: =IF( $F4>85, "From 86", IF( $F4>80, "81-85", IF( $F4>75, "76-80", IF( $F4>70, "71-75", IF( $F4>65, "66-70", IF( $F4>60, "61-65", IF( $F4>55, "56-60", IF( $F4>50, "51-55", IF( $F4>45, "46-50", IF( $F4>40, "41-45", IF( $F4>35, "36-40", IF( $F4>30, "31-35", IF($F4>25, "26-30", IF($F4>18,"19-25","0-18") ) ) ) ) ) ) ) ) ) ) ) ) ) -> From 86 | M4: =Table1[[#This Row],[Error_Name]] &Table1[[#This Row],[Error_DoB]] &Table1[[#This Row],[Error_Age]] &Table1[[#This Row],[Error_Gender]] &Table1[[#This Row],[Error_Relationship]] &Table1[[#This Row],[Error_Ph]] &Table1[[#This Row],[Error_Email]] &Table1[[#This Row],[Error_Duplicate]] &Table1[[#This Row],[Error_EmployeeID]] -> Please enter Member Name. Invalid gender. Invalid relationship to employee. | N4: =IF(ISNUMBER(MATCH(Table1[[#This Row],[Relationship to Self]],[1]!Table4[Valid Relations],0)),"","Invalid relationship to employee. ") -> Invalid relationship to employee. | O4: =IF( Table1[[#This Row],[Relationship to Self]]=[1]Valid!$C$6, IF(AND(Table1[[#This Row],[Age]]>=[1]Valid!$D$6,Table1[[#This Row],[Age]]<=[1]Valid!$E$6),"",[1]Valid!$C$6 & " age should be between " & [1]Valid!$D$6 & " and " & [1]Valid!$E$6 & ". "), IF( Table1[[#This Row],[Relationship to Self]]=[1]Valid!$C$2, IF(AND(Table1[[#This Row],[Age]]>=[1]Valid!$D$2,Table1[[#This Row],[Age]]<=[1]Valid!$E$2),"",[1]Valid!$C$2 & " age should be between " & [1]Valid!$D$2 & " and " & [1]Valid!$E$2 & ". "), IF( Table1[[#This Row],[Relationship to Self]]=[1]Valid!$C$3, IF(AND(Table1[[#This Row],[Age]]>=[1]Valid!$D$3,Table1[[#This Row],[Age]]<=[1]Valid!$E$3),"",[1]Valid!$C$3 & " age should be between " & [1]Valid!$D$3 & " and " & [1]Valid!$E$3 & ". "), IF( Table1[[#This Row],[Relationship to Self]]=[1]Valid!$C$4, IF(AND(Table1[[#This Row],[Age]]>=[1]Valid!$D$4,Table1[[#This Row],[Age]]<=[1]Valid!$E$4),"",[1]Valid!$C$4 & " age should be between " & [1]Valid!$D$4 & " and " & [1]Valid!$E$4 & ". "), IF( Table1[[#This Row],[Relationship to Self]]=[1]Valid!$C$5, IF(AND(Table1[[#This Row],[Age]]>=[1]Valid!$D$5,Table1[[#This Row],[Age]]<=[1]Valid!$E$5),"",[1]Valid!$C$5 & " age should be between " & [1]Valid!$D$5 & " and " & [1]Valid!$E$5 & ". "), "" ) ) ) ) ) | P4: =IF(ISNUMBER(MATCH(Table1[[#This Row],[Gender]],[1]!Table6[Gender],0)),"","Invalid gender. ") -> Invalid gender. | Q4: =IF(Table1[[#This Row],[Relationship to Self]]<>"Self","",IF(AND(Table1[[#This Row],[Mobile Number]]>6000000000,Table1[[#This Row],[Mobile Number]]<9999999999),"","The entered mobile number is invalid. ")) | R4: {=IF(Table1[[#This Row],[Relationship to Self]]<>"Self","",IF(IsEmailValid(Table1[[#This Row],[Email]]),IF(ISNUMBER(SEARCH([1]Valid!$K$1,Table1[[#This Row],[Email]])),"","The entered email is not corporate email. "),"The entered email is invalid. "))} | S4: =IF(Table1[[#This Row],[Member Name]]="","Please enter Member Name. ","") -> Please enter Member Name. | T4: =IF(YEAR(Table1[[#This Row],[Date of Birth]])=1905, "DoB is incomplete. ","") | U4: =IF(COUNTIFS(Table1[Employee ID],Table1[[#This Row],[Employee ID]],Table1[Date of Birth],Table1[[#This Row],[Date of Birth]],Table1[Relationship to Self],Table1[[#This Row],[Relationship to Self]],Table1[Member Name],Table1[[#This Row],[Member Name]])>1,"This entry is repeated multiple times. ","") | V4: =IF(COUNTIFS(Table1[Employee ID],Table1[[#This Row],[Employee ID]],Table1[Relationship to Self],"Self")>1, "Duplicate Employee ID","")
A5: =ROW()-2 -> 3 | F5: =DATEDIF(E5,TODAY(),"y") -> 126 | G5: =IF( $F5>85, "From 86", IF( $F5>80, "81-85", IF( $F5>75, "76-80", IF( $F5>70, "71-75", IF( $F5>65, "66-70", IF( $F5>60, "61-65", IF( $F5>55, "56-60", IF( $F5>50, "51-55", IF( $F5>45, "46-50", IF( $F5>40, "41-45", IF( $F5>35, "36-40", IF( $F5>30, "31-35", IF($F5>25, "26-30", IF($F5>18,"19-25","0-18") ) ) ) ) ) ) ) ) ) ) ) ) ) -> From 86 | M5: =Table1[[#This Row],[Error_Name]] &Table1[[#This Row],[Error_DoB]] &Table1[[#This Row],[Error_Age]] &Table1[[#This Row],[Error_Gender]] &Table1[[#This Row],[Error_Relationship]] &Table1[[#This Row],[Error_Ph]] &Table1[[#This Row],[Error_Email]] &Table1[[#This Row],[Error_Duplicate]] &Table1[[#This Row],[Error_EmployeeID]] -> Please enter Member Name. Invalid gender. Invalid relationship to employee. | N5: =IF(ISNUMBER(MATCH(Table1[[#This Row],[Relationship to Self]],[1]!Table4[Valid Relations],0)),"","Invalid relationship to employee. ") -> Invalid relationship to employee. | O5: =IF( Table1[[#This Row],[Relationship to Self]]=[1]Valid!$C$6, IF(AND(Table1[[#This Row],[Age]]>=[1]Valid!$D$6,Table1[[#This Row],[Age]]<=[1]Valid!$E$6),"",[1]Valid!$C$6 & " age should be between " & [1]Valid!$D$6 & " and " & [1]Valid!$E$6 & ". "), IF( Table1[[#This Row],[Relationship to Self]]=[1]Valid!$C$2, IF(AND(Table1[[#This Row],[Age]]>=[1]Valid!$D$2,Table1[[#This Row],[Age]]<=[1]Valid!$E$2),"",[1]Valid!$C$2 & " age should be between " & [1]Valid!$D$2 & " and " & [1]Valid!$E$2 & ". "), IF( Table1[[#This Row],[Relationship to Self]]=[1]Valid!$C$3, IF(AND(Table1[[#This Row],[Age]]>=[1]Valid!$D$3,Table1[[#This Row],[Age]]<=[1]Valid!$E$3),"",[1]Valid!$C$3 & " age should be between " & [1]Valid!$D$3 & " and " & [1]Valid!$E$3 & ". "), IF( Table1[[#This Row],[Relationship to Self]]=[1]Valid!$C$4, IF(AND(Table1[[#This Row],[Age]]>=[1]Valid!$D$4,Table1[[#This Row],[Age]]<=[1]Valid!$E$4),"",[1]Valid!$C$4 & " age should be between " & [1]Valid!$D$4 & " and " & [1]Valid!$E$4 & ". "), IF( Table1[[#This Row],[Relationship to Self]]=[1]Valid!$C$5, IF(AND(Table1[[#This Row],[Age]]>=[1]Valid!$D$5,Table1[[#This Row],[Age]]<=[1]Valid!$E$5),"",[1]Valid!$C$5 & " age should be between " & [1]Valid!$D$5 & " and " & [1]Valid!$E$5 & ". "), "" ) ) ) ) ) | P5: =IF(ISNUMBER(MATCH(Table1[[#This Row],[Gender]],[1]!Table6[Gender],0)),"","Invalid gender. ") -> Invalid gender. | Q5: =IF(Table1[[#This Row],[Relationship to Self]]<>"Self","",IF(AND(Table1[[#This Row],[Mobile Number]]>6000000000,Table1[[#This Row],[Mobile Number]]<9999999999),"","The entered mobile number is invalid. ")) | R5: {=IF(Table1[[#This Row],[Relationship to Self]]<>"Self","",IF(IsEmailValid(Table1[[#This Row],[Email]]),IF(ISNUMBER(SEARCH([1]Valid!$K$1,Table1[[#This Row],[Email]])),"","The entered email is not corporate email. "),"The entered email is invalid. "))} | S5: =IF(Table1[[#This Row],[Member Name]]="","Please enter Member Name. ","") -> Please enter Member Name. | T5: =IF(YEAR(Table1[[#This Row],[Date of Birth]])=1905, "DoB is incomplete. ","") | U5: =IF(COUNTIFS(Table1[Employee ID],Table1[[#This Row],[Employee ID]],Table1[Date of Birth],Table1[[#This Row],[Date of Birth]],Table1[Relationship to Self],Table1[[#This Row],[Relationship to Self]],Table1[Member Name],Table1[[#This Row],[Member Name]])>1,"This entry is repeated multiple times. ","") | V5: =IF(COUNTIFS(Table1[Employee ID],Table1[[#This Row],[Employee ID]],Table1[Relationship to Self],"Self")>1, "Duplicate Employee ID","")
A6: =ROW()-2 -> 4 | F6: =DATEDIF(E6,TODAY(),"y") -> 126 | G6: =IF( $F6>85, "From 86", IF( $F6>80, "81-85", IF( $F6>75, "76-80", IF( $F6>70, "71-75", IF( $F6>65, "66-70", IF( $F6>60, "61-65", IF( $F6>55, "56-60", IF( $F6>50, "51-55", IF( $F6>45, "46-50", IF( $F6>40, "41-45", IF( $F6>35, "36-40", IF( $F6>30, "31-35", IF($F6>25, "26-30", IF($F6>18,"19-25","0-18") ) ) ) ) ) ) ) ) ) ) ) ) ) -> From 86 | M6: =Table1[[#This Row],[Error_Name]] &Table1[[#This Row],[Error_DoB]] &Table1[[#This Row],[Error_Age]] &Table1[[#This Row],[Error_Gender]] &Table1[[#This Row],[Error_Relationship]] &Table1[[#This Row],[Error_Ph]] &Table1[[#This Row],[Error_Email]] &Table1[[#This Row],[Error_Duplicate]] &Table1[[#This Row],[Error_EmployeeID]] -> Please enter Member Name. Invalid gender. Invalid relationship to employee. | N6: =IF(ISNUMBER(MATCH(Table1[[#This Row],[Relationship to Self]],[1]!Table4[Valid Relations],0)),"","Invalid relationship to employee. ") -> Invalid relationship to employee. | O6: =IF( Table1[[#This Row],[Relationship to Self]]=[1]Valid!$C$6, IF(AND(Table1[[#This Row],[Age]]>=[1]Valid!$D$6,Table1[[#This Row],[Age]]<=[1]Valid!$E$6),"",[1]Valid!$C$6 & " age should be between " & [1]Valid!$D$6 & " and " & [1]Valid!$E$6 & ". "), IF( Table1[[#This Row],[Relationship to Self]]=[1]Valid!$C$2, IF(AND(Table1[[#This Row],[Age]]>=[1]Valid!$D$2,Table1[[#This Row],[Age]]<=[1]Valid!$E$2),"",[1]Valid!$C$2 & " age should be between " & [1]Valid!$D$2 & " and " & [1]Valid!$E$2 & ". "), IF( Table1[[#This Row],[Relationship to Self]]=[1]Valid!$C$3, IF(AND(Table1[[#This Row],[Age]]>=[1]Valid!$D$3,Table1[[#This Row],[Age]]<=[1]Valid!$E$3),"",[1]Valid!$C$3 & " age should be between " & [1]Valid!$D$3 & " and " & [1]Valid!$E$3 & ". "), IF( Table1[[#This Row],[Relationship to Self]]=[1]Valid!$C$4, IF(AND(Table1[[#This Row],[Age]]>=[1]Valid!$D$4,Table1[[#This Row],[Age]]<=[1]Valid!$E$4),"",[1]Valid!$C$4 & " age should be between " & [1]Valid!$D$4 & " and " & [1]Valid!$E$4 & ". "), IF( Table1[[#This Row],[Relationship to Self]]=[1]Valid!$C$5, IF(AND(Table1[[#This Row],[Age]]>=[1]Valid!$D$5,Table1[[#This Row],[Age]]<=[1]Valid!$E$5),"",[1]Valid!$C$5 & " age should be between " & [1]Valid!$D$5 & " and " & [1]Valid!$E$5 & ". "), "" ) ) ) ) ) | P6: =IF(ISNUMBER(MATCH(Table1[[#This Row],[Gender]],[1]!Table6[Gender],0)),"","Invalid gender. ") -> Invalid gender. | Q6: =IF(Table1[[#This Row],[Relationship to Self]]<>"Self","",IF(AND(Table1[[#This Row],[Mobile Number]]>6000000000,Table1[[#This Row],[Mobile Number]]<9999999999),"","The entered mobile number is invalid. ")) | R6: {=IF(Table1[[#This Row],[Relationship to Self]]<>"Self","",IF(IsEmailValid(Table1[[#This Row],[Email]]),IF(ISNUMBER(SEARCH([1]Valid!$K$1,Table1[[#This Row],[Email]])),"","The entered email is not corporate email. "),"The entered email is invalid. "))} | S6: =IF(Table1[[#This Row],[Member Name]]="","Please enter Member Name. ","") -> Please enter Member Name. | T6: =IF(YEAR(Table1[[#This Row],[Date of Birth]])=1905, "DoB is incomplete. ","") | U6: =IF(COUNTIFS(Table1[Employee ID],Table1[[#This Row],[Employee ID]],Table1[Date of Birth],Table1[[#This Row],[Date of Birth]],Table1[Relationship to Self],Table1[[#This Row],[Relationship to Self]],Table1[Member Name],Table1[[#This Row],[Member Name]])>1,"This entry is repeated multiple times. ","") | V6: =IF(COUNTIFS(Table1[Employee ID],Table1[[#This Row],[Employee ID]],Table1[Relationship to Self],"Self")>1, "Duplicate Employee ID","")
A7: =ROW()-2 -> 5 | F7: =DATEDIF(E7,TODAY(),"y") -> 126 | G7: =IF( $F7>85, "From 86", IF( $F7>80, "81-85", IF( $F7>75, "76-80", IF( $F7>70, "71-75", IF( $F7>65, "66-70", IF( $F7>60, "61-65", IF( $F7>55, "56-60", IF( $F7>50, "51-55", IF( $F7>45, "46-50", IF( $F7>40, "41-45", IF( $F7>35, "36-40", IF( $F7>30, "31-35", IF($F7>25, "26-30", IF($F7>18,"19-25","0-18") ) ) ) ) ) ) ) ) ) ) ) ) ) -> From 86 | M7: =Table1[[#This Row],[Error_Name]] &Table1[[#This Row],[Error_DoB]] &Table1[[#This Row],[Error_Age]] &Table1[[#This Row],[Error_Gender]] &Table1[[#This Row],[Error_Relationship]] &Table1[[#This Row],[Error_Ph]] &Table1[[#This Row],[Error_Email]] &Table1[[#This Row],[Error_Duplicate]] &Table1[[#This Row],[Error_EmployeeID]] -> Please enter Member Name. Invalid gender. Invalid relationship to employee. | N7: =IF(ISNUMBER(MATCH(Table1[[#This Row],[Relationship to Self]],[1]!Table4[Valid Relations],0)),"","Invalid relationship to employee. ") -> Invalid relationship to employee. | O7: =IF( Table1[[#This Row],[Relationship to Self]]=[1]Valid!$C$6, IF(AND(Table1[[#This Row],[Age]]>=[1]Valid!$D$6,Table1[[#This Row],[Age]]<=[1]Valid!$E$6),"",[1]Valid!$C$6 & " age should be between " & [1]Valid!$D$6 & " and " & [1]Valid!$E$6 & ". "), IF( Table1[[#This Row],[Relationship to Self]]=[1]Valid!$C$2, IF(AND(Table1[[#This Row],[Age]]>=[1]Valid!$D$2,Table1[[#This Row],[Age]]<=[1]Valid!$E$2),"",[1]Valid!$C$2 & " age should be between " & [1]Valid!$D$2 & " and " & [1]Valid!$E$2 & ". "), IF( Table1[[#This Row],[Relationship to Self]]=[1]Valid!$C$3, IF(AND(Table1[[#This Row],[Age]]>=[1]Valid!$D$3,Table1[[#This Row],[Age]]<=[1]Valid!$E$3),"",[1]Valid!$C$3 & " age should be between " & [1]Valid!$D$3 & " and " & [1]Valid!$E$3 & ". "), IF( Table1[[#This Row],[Relationship to Self]]=[1]Valid!$C$4, IF(AND(Table1[[#This Row],[Age]]>=[1]Valid!$D$4,Table1[[#This Row],[Age]]<=[1]Valid!$E$4),"",[1]Valid!$C$4 & " age should be between " & [1]Valid!$D$4 & " and " & [1]Valid!$E$4 & ". "), IF( Table1[[#This Row],[Relationship to Self]]=[1]Valid!$C$5, IF(AND(Table1[[#This Row],[Age]]>=[1]Valid!$D$5,Table1[[#This Row],[Age]]<=[1]Valid!$E$5),"",[1]Valid!$C$5 & " age should be between " & [1]Valid!$D$5 & " and " & [1]Valid!$E$5 & ". "), "" ) ) ) ) ) | P7: =IF(ISNUMBER(MATCH(Table1[[#This Row],[Gender]],[1]!Table6[Gender],0)),"","Invalid gender. ") -> Invalid gender. | Q7: =IF(Table1[[#This Row],[Relationship to Self]]<>"Self","",IF(AND(Table1[[#This Row],[Mobile Number]]>6000000000,Table1[[#This Row],[Mobile Number]]<9999999999),"","The entered mobile number is invalid. ")) | R7: {=IF(Table1[[#This Row],[Relationship to Self]]<>"Self","",IF(IsEmailValid(Table1[[#This Row],[Email]]),IF(ISNUMBER(SEARCH([1]Valid!$K$1,Table1[[#This Row],[Email]])),"","The entered email is not corporate email. "),"The entered email is invalid. "))} | S7: =IF(Table1[[#This Row],[Member Name]]="","Please enter Member Name. ","") -> Please enter Member Name. | T7: =IF(YEAR(Table1[[#This Row],[Date of Birth]])=1905, "DoB is incomplete. ","") | U7: =IF(COUNTIFS(Table1[Employee ID],Table1[[#This Row],[Employee ID]],Table1[Date of Birth],Table1[[#This Row],[Date of Birth]],Table1[Relationship to Self],Table1[[#This Row],[Relationship to Self]],Table1[Member Name],Table1[[#This Row],[Member Name]])>1,"This entry is repeated multiple times. ","") | V7: =IF(COUNTIFS(Table1[Employee ID],Table1[[#This Row],[Employee ID]],Table1[Relationship to Self],"Self")>1, "Duplicate Employee ID","")
A8: =ROW()-2 -> 6 | F8: =DATEDIF(E8,TODAY(),"y") -> 126 | G8: =IF( $F8>85, "From 86", IF( $F8>80, "81-85", IF( $F8>75, "76-80", IF( $F8>70, "71-75", IF( $F8>65, "66-70", IF( $F8>60, "61-65", IF( $F8>55, "56-60", IF( $F8>50, "51-55", IF( $F8>45, "46-50", IF( $F8>40, "41-45", IF( $F8>35, "36-40", IF( $F8>30, "31-35", IF($F8>25, "26-30", IF($F8>18,"19-25","0-18") ) ) ) ) ) ) ) ) ) ) ) ) ) -> From 86 | M8: =Table1[[#This Row],[Error_Name]] &Table1[[#This Row],[Error_DoB]] &Table1[[#This Row],[Error_Age]] &Table1[[#This Row],[Error_Gender]] &Table1[[#This Row],[Error_Relationship]] &Table1[[#This Row],[Error_Ph]] &Table1[[#This Row],[Error_Email]] &Table1[[#This Row],[Error_Duplicate]] &Table1[[#This Row],[Error_EmployeeID]] -> Please enter Member Name. Invalid gender. Invalid relationship to employee. | N8: =IF(ISNUMBER(MATCH(Table1[[#This Row],[Relationship to Self]],[1]!Table4[Valid Relations],0)),"","Invalid relationship to employee. ") -> Invalid relationship to employee. | O8: =IF( Table1[[#This Row],[Relationship to Self]]=[1]Valid!$C$6, IF(AND(Table1[[#This Row],[Age]]>=[1]Valid!$D$6,Table1[[#This Row],[Age]]<=[1]Valid!$E$6),"",[1]Valid!$C$6 & " age should be between " & [1]Valid!$D$6 & " and " & [1]Valid!$E$6 & ". "), IF( Table1[[#This Row],[Relationship to Self]]=[1]Valid!$C$2, IF(AND(Table1[[#This Row],[Age]]>=[1]Valid!$D$2,Table1[[#This Row],[Age]]<=[1]Valid!$E$2),"",[1]Valid!$C$2 & " age should be between " & [1]Valid!$D$2 & " and " & [1]Valid!$E$2 & ". "), IF( Table1[[#This Row],[Relationship to Self]]=[1]Valid!$C$3, IF(AND(Table1[[#This Row],[Age]]>=[1]Valid!$D$3,Table1[[#This Row],[Age]]<=[1]Valid!$E$3),"",[1]Valid!$C$3 & " age should be between " & [1]Valid!$D$3 & " and " & [1]Valid!$E$3 & ". "), IF( Table1[[#This Row],[Relationship to Self]]=[1]Valid!$C$4, IF(AND(Table1[[#This Row],[Age]]>=[1]Valid!$D$4,Table1[[#This Row],[Age]]<=[1]Valid!$E$4),"",[1]Valid!$C$4 & " age should be between " & [1]Valid!$D$4 & " and " & [1]Valid!$E$4 & ". "), IF( Table1[[#This Row],[Relationship to Self]]=[1]Valid!$C$5, IF(AND(Table1[[#This Row],[Age]]>=[1]Valid!$D$5,Table1[[#This Row],[Age]]<=[1]Valid!$E$5),"",[1]Valid!$C$5 & " age should be between " & [1]Valid!$D$5 & " and " & [1]Valid!$E$5 & ". "), "" ) ) ) ) ) | P8: =IF(ISNUMBER(MATCH(Table1[[#This Row],[Gender]],[1]!Table6[Gender],0)),"","Invalid gender. ") -> Invalid gender. | Q8: =IF(Table1[[#This Row],[Relationship to Self]]<>"Self","",IF(AND(Table1[[#This Row],[Mobile Number]]>6000000000,Table1[[#This Row],[Mobile Number]]<9999999999),"","The entered mobile number is invalid. ")) | R8: {=IF(Table1[[#This Row],[Relationship to Self]]<>"Self","",IF(IsEmailValid(Table1[[#This Row],[Email]]),IF(ISNUMBER(SEARCH([1]Valid!$K$1,Table1[[#This Row],[Email]])),"","The entered email is not corporate email. "),"The entered email is invalid. "))} | S8: =IF(Table1[[#This Row],[Member Name]]="","Please enter Member Name. ","") -> Please enter Member Name. | T8: =IF(YEAR(Table1[[#This Row],[Date of Birth]])=1905, "DoB is incomplete. ","") | U8: =IF(COUNTIFS(Table1[Employee ID],Table1[[#This Row],[Employee ID]],Table1[Date of Birth],Table1[[#This Row],[Date of Birth]],Table1[Relationship to Self],Table1[[#This Row],[Relationship to Self]],Table1[Member Name],Table1[[#This Row],[Member Name]])>1,"This entry is repeated multiple times. ","") | V8: =IF(COUNTIFS(Table1[Employee ID],Table1[[#This Row],[Employee ID]],Table1[Relationship to Self],"Self")>1, "Duplicate Employee ID","")
A9: =ROW()-2 -> 7 | F9: =DATEDIF(E9,TODAY(),"y") -> 126 | G9: =IF( $F9>85, "From 86", IF( $F9>80, "81-85", IF( $F9>75, "76-80", IF( $F9>70, "71-75", IF( $F9>65, "66-70", IF( $F9>60, "61-65", IF( $F9>55, "56-60", IF( $F9>50, "51-55", IF( $F9>45, "46-50", IF( $F9>40, "41-45", IF( $F9>35, "36-40", IF( $F9>30, "31-35", IF($F9>25, "26-30", IF($F9>18,"19-25","0-18") ) ) ) ) ) ) ) ) ) ) ) ) ) -> From 86 | M9: =Table1[[#This Row],[Error_Name]] &Table1[[#This Row],[Error_DoB]] &Table1[[#This Row],[Error_Age]] &Table1[[#This Row],[Error_Gender]] &Table1[[#This Row],[Error_Relationship]] &Table1[[#This Row],[Error_Ph]] &Table1[[#This Row],[Error_Email]] &Table1[[#This Row],[Error_Duplicate]] &Table1[[#This Row],[Error_EmployeeID]] -> Please enter Member Name. Invalid gender. Invalid relationship to employee. | N9: =IF(ISNUMBER(MATCH(Table1[[#This Row],[Relationship to Self]],[1]!Table4[Valid Relations],0)),"","Invalid relationship to employee. ") -> Invalid relationship to employee. | O9: =IF( Table1[[#This Row],[Relationship to Self]]=[1]Valid!$C$6, IF(AND(Table1[[#This Row],[Age]]>=[1]Valid!$D$6,Table1[[#This Row],[Age]]<=[1]Valid!$E$6),"",[1]Valid!$C$6 & " age should be between " & [1]Valid!$D$6 & " and " & [1]Valid!$E$6 & ". "), IF( Table1[[#This Row],[Relationship to Self]]=[1]Valid!$C$2, IF(AND(Table1[[#This Row],[Age]]>=[1]Valid!$D$2,Table1[[#This Row],[Age]]<=[1]Valid!$E$2),"",[1]Valid!$C$2 & " age should be between " & [1]Valid!$D$2 & " and " & [1]Valid!$E$2 & ". "), IF( Table1[[#This Row],[Relationship to Self]]=[1]Valid!$C$3, IF(AND(Table1[[#This Row],[Age]]>=[1]Valid!$D$3,Table1[[#This Row],[Age]]<=[1]Valid!$E$3),"",[1]Valid!$C$3 & " age should be between " & [1]Valid!$D$3 & " and " & [1]Valid!$E$3 & ". "), IF( Table1[[#This Row],[Relationship to Self]]=[1]Valid!$C$4, IF(AND(Table1[[#This Row],[Age]]>=[1]Valid!$D$4,Table1[[#This Row],[Age]]<=[1]Valid!$E$4),"",[1]Valid!$C$4 & " age should be between " & [1]Valid!$D$4 & " and " & [1]Valid!$E$4 & ". "), IF( Table1[[#This Row],[Relationship to Self]]=[1]Valid!$C$5, IF(AND(Table1[[#This Row],[Age]]>=[1]Valid!$D$5,Table1[[#This Row],[Age]]<=[1]Valid!$E$5),"",[1]Valid!$C$5 & " age should be between " & [1]Valid!$D$5 & " and " & [1]Valid!$E$5 & ". "), "" ) ) ) ) ) | P9: =IF(ISNUMBER(MATCH(Table1[[#This Row],[Gender]],[1]!Table6[Gender],0)),"","Invalid gender. ") -> Invalid gender. | Q9: =IF(Table1[[#This Row],[Relationship to Self]]<>"Self","",IF(AND(Table1[[#This Row],[Mobile Number]]>6000000000,Table1[[#This Row],[Mobile Number]]<9999999999),"","The entered mobile number is invalid. ")) | R9: {=IF(Table1[[#This Row],[Relationship to Self]]<>"Self","",IF(IsEmailValid(Table1[[#This Row],[Email]]),IF(ISNUMBER(SEARCH([1]Valid!$K$1,Table1[[#This Row],[Email]])),"","The entered email is not corporate email. "),"The entered email is invalid. "))} | S9: =IF(Table1[[#This Row],[Member Name]]="","Please enter Member Name. ","") -> Please enter Member Name. | T9: =IF(YEAR(Table1[[#This Row],[Date of Birth]])=1905, "DoB is incomplete. ","") | U9: =IF(COUNTIFS(Table1[Employee ID],Table1[[#This Row],[Employee ID]],Table1[Date of Birth],Table1[[#This Row],[Date of Birth]],Table1[Relationship to Self],Table1[[#This Row],[Relationship to Self]],Table1[Member Name],Table1[[#This Row],[Member Name]])>1,"This entry is repeated multiple times. ","") | V9: =IF(COUNTIFS(Table1[Employee ID],Table1[[#This Row],[Employee ID]],Table1[Relationship to Self],"Self")>1, "Duplicate Employee ID","")
A10: =ROW()-2 -> 8 | F10: =DATEDIF(E10,TODAY(),"y") -> 126 | G10: =IF( $F10>85, "From 86", IF( $F10>80, "81-85", IF( $F10>75, "76-80", IF( $F10>70, "71-75", IF( $F10>65, "66-70", IF( $F10>60, "61-65", IF( $F10>55, "56-60", IF( $F10>50, "51-55", IF( $F10>45, "46-50", IF( $F10>40, "41-45", IF( $F10>35, "36-40", IF( $F10>30, "31-35", IF($F10>25, "26-30", IF($F10>18,"19-25","0-18") ) ) ) ) ) ) ) ) ) ) ) ) ) -> From 86 | M10: =Table1[[#This Row],[Error_Name]] &Table1[[#This Row],[Error_DoB]] &Table1[[#This Row],[Error_Age]] &Table1[[#This Row],[Error_Gender]] &Table1[[#This Row],[Error_Relationship]] &Table1[[#This Row],[Error_Ph]] &Table1[[#This Row],[Error_Email]] &Table1[[#This Row],[Error_Duplicate]] &Table1[[#This Row],[Error_EmployeeID]] -> Please enter Member Name. Invalid gender. Invalid relationship to employee. | N10: =IF(ISNUMBER(MATCH(Table1[[#This Row],[Relationship to Self]],[1]!Table4[Valid Relations],0)),"","Invalid relationship to employee. ") -> Invalid relationship to employee. | O10: =IF( Table1[[#This Row],[Relationship to Self]]=[1]Valid!$C$6, IF(AND(Table1[[#This Row],[Age]]>=[1]Valid!$D$6,Table1[[#This Row],[Age]]<=[1]Valid!$E$6),"",[1]Valid!$C$6 & " age should be between " & [1]Valid!$D$6 & " and " & [1]Valid!$E$6 & ". "), IF( Table1[[#This Row],[Relationship to Self]]=[1]Valid!$C$2, IF(AND(Table1[[#This Row],[Age]]>=[1]Valid!$D$2,Table1[[#This Row],[Age]]<=[1]Valid!$E$2),"",[1]Valid!$C$2 & " age should be between " & [1]Valid!$D$2 & " and " & [1]Valid!$E$2 & ". "), IF( Table1[[#This Row],[Relationship to Self]]=[1]Valid!$C$3, IF(AND(Table1[[#This Row],[Age]]>=[1]Valid!$D$3,Table1[[#This Row],[Age]]<=[1]Valid!$E$3),"",[1]Valid!$C$3 & " age should be between " & [1]Valid!$D$3 & " and " & [1]Valid!$E$3 & ". "), IF( Table1[[#This Row],[Relationship to Self]]=[1]Valid!$C$4, IF(AND(Table1[[#This Row],[Age]]>=[1]Valid!$D$4,Table1[[#This Row],[Age]]<=[1]Valid!$E$4),"",[1]Valid!$C$4 & " age should be between " & [1]Valid!$D$4 & " and " & [1]Valid!$E$4 & ". "), IF( Table1[[#This Row],[Relationship to Self]]=[1]Valid!$C$5, IF(AND(Table1[[#This Row],[Age]]>=[1]Valid!$D$5,Table1[[#This Row],[Age]]<=[1]Valid!$E$5),"",[1]Valid!$C$5 & " age should be between " & [1]Valid!$D$5 & " and " & [1]Valid!$E$5 & ". "), "" ) ) ) ) ) | P10: =IF(ISNUMBER(MATCH(Table1[[#This Row],[Gender]],[1]!Table6[Gender],0)),"","Invalid gender. ") -> Invalid gender. | Q10: =IF(Table1[[#This Row],[Relationship to Self]]<>"Self","",IF(AND(Table1[[#This Row],[Mobile Number]]>6000000000,Table1[[#This Row],[Mobile Number]]<9999999999),"","The entered mobile number is invalid. ")) | R10: {=IF(Table1[[#This Row],[Relationship to Self]]<>"Self","",IF(IsEmailValid(Table1[[#This Row],[Email]]),IF(ISNUMBER(SEARCH([1]Valid!$K$1,Table1[[#This Row],[Email]])),"","The entered email is not corporate email. "),"The entered email is invalid. "))} | S10: =IF(Table1[[#This Row],[Member Name]]="","Please enter Member Name. ","") -> Please enter Member Name. | T10: =IF(YEAR(Table1[[#This Row],[Date of Birth]])=1905, "DoB is incomplete. ","") | U10: =IF(COUNTIFS(Table1[Employee ID],Table1[[#This Row],[Employee ID]],Table1[Date of Birth],Table1[[#This Row],[Date of Birth]],Table1[Relationship to Self],Table1[[#This Row],[Relationship to Self]],Table1[Member Name],Table1[[#This Row],[Member Name]])>1,"This entry is repeated multiple times. ","") | V10: =IF(COUNTIFS(Table1[Employee ID],Table1[[#This Row],[Employee ID]],Table1[Relationship to Self],"Self")>1, "Duplicate Employee ID","")
A11: =ROW()-2 -> 9 | F11: =DATEDIF(E11,TODAY(),"y") -> 126 | G11: =IF( $F11>85, "From 86", IF( $F11>80, "81-85", IF( $F11>75, "76-80", IF( $F11>70, "71-75", IF( $F11>65, "66-70", IF( $F11>60, "61-65", IF( $F11>55, "56-60", IF( $F11>50, "51-55", IF( $F11>45, "46-50", IF( $F11>40, "41-45", IF( $F11>35, "36-40", IF( $F11>30, "31-35", IF($F11>25, "26-30", IF($F11>18,"19-25","0-18") ) ) ) ) ) ) ) ) ) ) ) ) ) -> From 86 | M11: =Table1[[#This Row],[Error_Name]] &Table1[[#This Row],[Error_DoB]] &Table1[[#This Row],[Error_Age]] &Table1[[#This Row],[Error_Gender]] &Table1[[#This Row],[Error_Relationship]] &Table1[[#This Row],[Error_Ph]] &Table1[[#This Row],[Error_Email]] &Table1[[#This Row],[Error_Duplicate]] &Table1[[#This Row],[Error_EmployeeID]] -> Please enter Member Name. Invalid gender. Invalid relationship to employee. | N11: =IF(ISNUMBER(MATCH(Table1[[#This Row],[Relationship to Self]],[1]!Table4[Valid Relations],0)),"","Invalid relationship to employee. ") -> Invalid relationship to employee. | O11: =IF( Table1[[#This Row],[Relationship to Self]]=[1]Valid!$C$6, IF(AND(Table1[[#This Row],[Age]]>=[1]Valid!$D$6,Table1[[#This Row],[Age]]<=[1]Valid!$E$6),"",[1]Valid!$C$6 & " age should be between " & [1]Valid!$D$6 & " and " & [1]Valid!$E$6 & ". "), IF( Table1[[#This Row],[Relationship to Self]]=[1]Valid!$C$2, IF(AND(Table1[[#This Row],[Age]]>=[1]Valid!$D$2,Table1[[#This Row],[Age]]<=[1]Valid!$E$2),"",[1]Valid!$C$2 & " age should be between " & [1]Valid!$D$2 & " and " & [1]Valid!$E$2 & ". "), IF( Table1[[#This Row],[Relationship to Self]]=[1]Valid!$C$3, IF(AND(Table1[[#This Row],[Age]]>=[1]Valid!$D$3,Table1[[#This Row],[Age]]<=[1]Valid!$E$3),"",[1]Valid!$C$3 & " age should be between " & [1]Valid!$D$3 & " and " & [1]Valid!$E$3 & ". "), IF( Table1[[#This Row],[Relationship to Self]]=[1]Valid!$C$4, IF(AND(Table1[[#This Row],[Age]]>=[1]Valid!$D$4,Table1[[#This Row],[Age]]<=[1]Valid!$E$4),"",[1]Valid!$C$4 & " age should be between " & [1]Valid!$D$4 & " and " & [1]Valid!$E$4 & ". "), IF( Table1[[#This Row],[Relationship to Self]]=[1]Valid!$C$5, IF(AND(Table1[[#This Row],[Age]]>=[1]Valid!$D$5,Table1[[#This Row],[Age]]<=[1]Valid!$E$5),"",[1]Valid!$C$5 & " age should be between " & [1]Valid!$D$5 & " and " & [1]Valid!$E$5 & ". "), "" ) ) ) ) ) | P11: =IF(ISNUMBER(MATCH(Table1[[#This Row],[Gender]],[1]!Table6[Gender],0)),"","Invalid gender. ") -> Invalid gender. | Q11: =IF(Table1[[#This Row],[Relationship to Self]]<>"Self","",IF(AND(Table1[[#This Row],[Mobile Number]]>6000000000,Table1[[#This Row],[Mobile Number]]<9999999999),"","The entered mobile number is invalid. ")) | R11: {=IF(Table1[[#This Row],[Relationship to Self]]<>"Self","",IF(IsEmailValid(Table1[[#This Row],[Email]]),IF(ISNUMBER(SEARCH([1]Valid!$K$1,Table1[[#This Row],[Email]])),"","The entered email is not corporate email. "),"The entered email is invalid. "))} | S11: =IF(Table1[[#This Row],[Member Name]]="","Please enter Member Name. ","") -> Please enter Member Name. | T11: =IF(YEAR(Table1[[#This Row],[Date of Birth]])=1905, "DoB is incomplete. ","") | U11: =IF(COUNTIFS(Table1[Employee ID],Table1[[#This Row],[Employee ID]],Table1[Date of Birth],Table1[[#This Row],[Date of Birth]],Table1[Relationship to Self],Table1[[#This Row],[Relationship to Self]],Table1[Member Name],Table1[[#This Row],[Member Name]])>1,"This entry is repeated multiple times. ","") | V11: =IF(COUNTIFS(Table1[Employee ID],Table1[[#This Row],[Employee ID]],Table1[Relationship to Self],"Self")>1, "Duplicate Employee ID","")

Sheet Age Band Pivot
H2: Self and Spouse age more than 18
A3: Count of Relationship to Self | B3: Column Labels | H3: Children age less than 25
A4: Row Labels | B4: (blank) | C4: Grand Total | H4: Parents age more than 40
A5: From 86
A6: Grand Total

Sheet Claims Analysis
A1: Particulars | B1: No. of Claims | C1: Claims Paid (Rs.) | D1: Outstanding (Rs.) | E1: Claims Paid + O/S (Rs.) | F1: Highlighted in Claims MIS
A2: Total Claims | B2: 4 | C2: 350000 | D2: 20000 | E2: =C2+D2 -> 370000
A3: Major claims (>2 lacs) by employees who have exited the co | E3: =C3+D3 -> 0
A4: Major claims (>2 lacs) by members who have died | E4: =C4+D4 -> 0
A5: Accidental claims | E5: =C5+D5 -> 0
A6: Net Claims | B6: =B2-SUM(B3:B5) -> 4 | C6: =C2-SUM(C3:C5) -> 350000 | D6: =D2-SUM(D3:D5) -> 20000 | E6: =E2-SUM(E3:E5) -> 370000
A7: Claims which are non-recurring | E7: =C7+D7 -> 0
A8: Net Claims (excl. recurring claims) | B8: =B6-B7 -> 4 | C8: =C6-C7 -> 350000 | D8: =D6-D7 -> 20000 | E8: =E6-E7 -> 370000

Sheet Renewal Quote Predict
A1: Premium Calculator
B3: Policy period From | C3: 45753 | E3: No. of lives at the start of policy | F3: ='GHI RFQ'!B27 -> 100
B4: Policy period To | C4: =DATE(YEAR(C3)+1,MONTH(C3),DAY(C3)-1) -> 46117 | E4: No. of lives at the end of policy | F4: ='GHI RFQ'!C27 -> 200
B5: Claims MIS report generation date | C5: 46077 | E5: Simple Avg of lives in previous year | F5: =AVERAGE(F3:F4) -> 150
B6: Policy completed days | C6: =C4-C3+1-C7 -> 325 | E6: Weighted Avg of lives in previous year | F6: {=IFERROR(F3*'GHI RFQ'!D12:D12/'GHI RFQ'!D11:D11,"NA")} -> 166.66667
B7: Balance days | C7: =C4-C5 -> 40 | E7: Selected Average of lives in previous year | F7: =MAX(F6,F5) -> 166.66667
B8: Incurred But Not Reported cases in % | C8: 0.04 | E8: No of lives for renewal | F8: {='GHI RFQ'!D27:D27} -> 200
E9: % Change | F9: =F8/F7-1 -> 0.2
B11: Particulars | C11: Amount | E11: Buffer | F11: 0.05
B12: Amount of claims paid | C12: ='Claims Analysis'!C2 -> 350000 | E12: Inflation cost | F12: 0.05
B13: Outstanding claims (claims in process) | C13: ='Claims Analysis'!D2 -> 20000 | E13: Management Costs | F13: 0.05
B14: Total Claims | C14: =SUM(C12:C13) -> 370000
B15: Incurred But Not Reported Claims | C15: =C14*C8 -> 14800
B16: Total Claims as on date | C16: =SUM(C14:C15) -> 384800
B17: Claims for remainder period | C17: =C16/C6*C7 -> 47360
B18: Annualized Claims | C18: =SUM(C16:C17) -> 432160
B19: Claims Increase due to increase in no. of lives | C19: =C18*F9 -> 86432
B20: Expected claims for next year (Burning Costs) | C20: =SUM(C18:C19) -> 518592
B21: Buffer, Inflation, Management cost | C21: =C22-C20 -> 91516.235
B22: Total | C22: =C20/(1-SUM(F11:F14)) -> 610108.24

Sheet Records to be corrected
A1: Records to be corrected
A3: S.No. | B3: Employee ID | C3: Employment Type (On-Roll/Off-Roll) | D3: Member Name | E3: Date of Birth | F3: Age | G3: Age Band | H3: Gender | I3: Relationship to Self | J3: GHI Sum Insured | K3: Error

Sheet Age Band - Only PSU
A1: For 2 Lakhs Sum Insured
A2: Self | B2: 0-20 | C2: 21-25 | D2: 26-30 | E2: 31-35 | F2: 36-40 | G2: 41-45 | H2: 46-50 | I2: 51-55 | J2: 56-60 | K2: 61-65 | L2: 66-70 | M2: 71-75 | N2: 76-80 | O2: TOTAL
A3: Age Band | B3: 1 | C3: 51 | D3: 68 | E3: 56 | F3: 138 | G3: 167 | H3: 137 | I3: 104 | J3: 43 | K3: 0 | L3: 0 | M3: 0 | N3: 0 | O3: =SUM(B3:N3) -> 765
A5: Spouse | B5: 0-20 | C5: 21-25 | D5: 26-30 | E5: 31-35 | F5: 36-40 | G5: 41-45 | H5: 46-50 | I5: 51-55 | J5: 56-60 | K5: 61-65 | L5: 66-70 | M5: 71-75 | N5: 76-80 | O5: TOTAL
A6: Age Band | C6: 12 | D6: 48 | E6: 110 | F6: 162 | G6: 133 | H6: 78 | I6: 45 | J6: 4 | K6: 1 | L6: 0 | M6: 0 | N6: 0 | O6: =SUM(B6:N6) -> 593
A9: Children | B9: 0-20 | C9: 21-25 | D9: 26-30 | E9: 30+ | F9: TOTAL
A10: Age Band | B10: 694 | C10: 165 | D10: 0 | E10: 0 | F10: =SUM(B10:E10) -> 859
A12: Parents | B12: 36-40 | C12: 41-45 | D12: 46-50 | E12: 51-55 | F12: 56-60 | G12: 61-65 | H12: 66-70 | I12: 71-75 | J12: 76-80 | K12: 81-85 | L12: 85+ | M12: TOTAL
A13: Age Band | B13: 0 | C13: 0 | D13: 2 | E13: 8 | F13: 35 | G13: 39 | H13: 68 | I13: 56 | J13: 25 | K13: 13 | L13: 5 | M13: =SUM(B13:L13) -> 251
A15: For 3 Lakhs Sum Insured
A16: Self | B16: 0-20 | C16: 21-25 | D16: 26-30 | E16: 31-35 | F16: 36-40 | G16: 41-45 | H16: 46-50 | I16: 51-55 | J16: 56-60 | K16: 61-65 | L16: 66-70 | M16: 71-75 | N16: 76-80 | O16: TOTAL
A17: Age Band | B17: 8 | C17: 475 | D17: 627 | E17: 498 | F17: 316 | G17: 160 | H17: 93 | I17: 51 | J17: 12 | K17: 0 | L17: 0 | M17: 1 | N17: 0 | O17: =SUM(B17:N17) -> 2241
A19: Spouse | B19: 0-20 | C19: 21-25 | D19: 26-30 | E19: 31-35 | F19: 36-40 | G19: 41-45 | H19: 46-50 | I19: 51-55 | J19: 56-60 | K19: 61-65 | L19: 66-70 | M19: 71-75 | N19: 76-80 | O19: TOTAL
A20: Age Band | B20: 2 | C20: 54 | D20: 184 | E20: 268 | F20: 216 | G20: 110 | H20: 49 | I20: 17 | J20: 8 | K20: 3 | L20: 0 | M20: 0 | N20: 0 | O20: =SUM(B20:N20) -> 911
A23: Children | B23: 0-20 | C23: 21-25 | D23: 26-30 | E23: 30+ | F23: TOTAL
A24: Age Band | B24: 910 | C24: 43 | D24: 0 | E24: 0 | F24: =SUM(B24:E24) -> 953
A26: Parents | B26: 36-40 | C26: 41-45 | D26: 46-50 | E26: 51-55 | F26: 56-60 | G26: 61-65 | H26: 66-70 | I26: 71-75 | J26: 76-80 | K26: 81-85 | L26: 85+ | M26: TOTAL
A27: Age Band | B27: 0 | C27: 7 | D27: 46 | E27: 110 | F27: 183 | G27: 182 | H27: 163 | I27: 111 | J27: 39 | K27: 19 | L27: 3 | M27: =SUM(B27:L27) -> 863
A29: For 5 Lakhs Sum Insured
A30: Self | B30: 0-20 | C30: 21-25 | D30: 26-30 | E30: 31-35 | F30: 36-40 | G30: 41-45 | H30: 46-50 | I30: 51-55 | J30: 56-60 | K30: 61-65 | L30: 66-70 | M30: 71-75 | N30: 76-80 | O30: TOTAL
A31: Age Band | B31: 0 | C31: 0 | D31: 2 | E31: 25 | F31: 49 | G31: 67 | H31: 48 | I31: 27 | J31: 9 | K31: 3 | L31: 0 | M31: 1 | N31: - | O31: =SUM(B31:N31) -> 231
A33: Spouse | B33: 0-20 | C33: 21-25 | D33: 26-30 | E33: 31-35 | F33: 36-40 | G33: 41-45 | H33: 46-50 | I33: 51-55 | J33: 56-60 | K33: 61-65 | L33: 66-70 | M33: 71-75 | N33: 76-80 | O33: TOTAL
A34: Age Band | B34: 0 | C34: 0 | D34: 8 | E34: 32 | F34: 63 | G34: 49 | H34: 36 | I34: 17 | J34: 3 | K34: 1 | L34: 0 | M34: 1 | N34: 0 | O34: =SUM(B34:N34) -> 210
A36: Children | B36: 0-20 | C36: 21-25 | D36: 26-30 | E36: 30+ | F36: TOTAL | Q36: Self | R36: =O3+O17+O31 -> 3237
A37: Age Band | B37: 213 | C37: 30 | D37: 1 | E37: 0 | F37: =SUM(B37:E37) -> 244 | Q37: Spouse | R37: =O6+O20+O34 -> 1714
Q38: Children | R38: =F10+F24+F37 -> 2056
A39: Parents | B39: 36-40 | C39: 41-45 | D39: 46-50 | E39: 51-55 | F39: 56-60 | G39: 61-65 | H39: 66-70 | I39: 71-75 | J39: 76-80 | K39: 81-85 | L39: 85+ | M39: TOTAL | Q39: Parents | R39: =M13+M27+M40 -> 1276
A40: Age Band | B40: 0 | C40: 0 | D40: 1 | E40: 8 | F40: 16 | G40: 27 | H40: 44 | I40: 32 | J40: 20 | K40: 10 | L40: 4 | M40: =SUM(B40:L40) -> 162 | Q40: Total Lives | R40: =SUM(R36:R39) -> 8283
