Workbook
Name industry_master: [1]Master!$B$3:$B$15
Name option: [1]RFQ!$E$126:$E$127

Sheet QUOTE LETTER - Operations
B1: TATA AIG GENERAL INSURANCE COMPANY LIMITED
B2: QUOTATION AND PROPOSAL FORM GROUP ACCIDENT GUARD POLICY
B3: We have quoted following risk on the basis of information as available / shared with us, it should be same at the time of finalisation of the proposal. Please do inform us in case of any changes in claim information or any other risk factor, as it has implications on appropriate pricing of the risk
B4: Proposer Details
B5: Reference / Quote Number | C5: =Rater!G5 -> F/020726-mumbai | E5: Quote Date: | F5: =Rater!G6 -> 46183
B6: Name Of The Insured | C6: =Rater!G7 -> STAY VISTA PRIVATE LIMITED | E6: Plan Type | F6: =Rater!C28 -> Basic
B7: Risk Inception Date | C7: =Rater!G8 -> 46198 | E7: =[1]RFQ!A8 -> Policy status * | F7: =Rater!G11 -> Fresh
B8: Insured Location | C8: =Rater!G9 -> mumbai | E8: Category | F8: SME
B9: Intermediary Name | C9: =Rater!G10 -> Safetynet Innovations PVT LTD / 2350090000 | E9: Producer Code | F9: =RIGHT(Rater!G10,10) -> 2350090000
B10: Policy Details
B11: =PROPER("No. OF Lives") -> No. Of Lives | C11: =Rater!G13 -> 488
B12: Type of Policy | C12: =Rater!G12 -> Named
B13: Group Category | C13: =Rater!G14 -> Employer-Employee
B14: =PROPER("BUSINESS DESCRIPTION") -> Business Description | C14: =Rater!C29 -> IT / ITES / BPO / KPO
B15: Description of Insured | C15: =Rater!G15 -> Only Permanent Employees of the company are covered.
B16: =PROPER("AGE BRACKET") -> Age Bracket | C16: =Rater!G16 -> 18 Yrs To 70 Yrs; Only Capital Benefit For Age Above 65 Yrs
B17: Past claim details /Loss Ratio | C17: =Rater!G17 -> 0
B18: Branch | C18: =Rater!G18 -> Mumbai - Peninsula
B19: =[1]RFQ!A28 -> Sum Insured Category (For Employees Only) | C19: =[1]RFQ!B28 -> No of lives | D19: =[1]RFQ!C28 -> Per Person SI | E19: =[1]RFQ!D28 -> Total Sum Insured
B20: =[1]RFQ!A29 -> Category 1 | C20: =Rater!G13 -> 488 | D20: =IF(Rater!G19="Flat",Rater!C31,Rater!G31) -> 150000000 | E20: =IF(Rater!G19="Flat",C20*D20,Rater!G31) -> 150000000
B21: =[1]RFQ!A30 -> Category 2
B22: =[1]RFQ!A31 -> Category 3
B23: =[1]RFQ!A32 -> Category 4
B24: =[1]RFQ!A33 -> Category 5
B25: =[1]RFQ!A34 -> Category 6
B26: =[1]RFQ!A35 -> Category 7
B27: =[1]RFQ!A36 -> Category 8
B28: =[1]RFQ!A37 -> Category 9
B29: =[1]RFQ!A38 -> Category 10
B30: =[1]RFQ!A39 -> Total | C30: =SUM(C20:C29) -> 488 | D30: =SUM(D20:D29) -> 150000000 | E30: =SUM(E20:E29) -> 150000000
B31: Description of Insured | C31: =[1]RFQ!C57 -> Only Permanent Employees of the company are covered.
B33: =PROPER("BENEFITS OFFERED") -> Benefits Offered | C33: SUM INSURED | D33: =PROPER(IF([1]RFQ!C46="EDUCATIONAL INSTITUTE","STAFF","EMPLOYEES")) -> Employees | E33: =PROPER(IF(C14="EDUCATIONAL INSTITUTE","STUDENT","")) | G33: =PROPER(IF(C14="EDUCATIONAL INSTITUTE","PARENT",""))
B34: Number of Insured | D34: =Rater!C32 -> 488 | E34: =IF([1]RFQ!C46="Educational Institute",IF(D34=0," ",[1]RFQ!D56),"") | G34: =IF([1]RFQ!C46="Educational Institute",IF(D34=0," ",[1]RFQ!E56),"")
B35: =IF(SUM([1]RFQ!C60:E60)>0,"Accidental Death","") -> Accidental Death | D35: =D20 -> 150000000 | E35: =IF([1]RFQ!$C$46="Educational Institute",[1]RFQ!D60,"") | G35: =IF([1]RFQ!$C$46="Educational Institute",[1]RFQ!E60,"")
B36: =IF(SUM([1]RFQ!C61:E61)>0,"Accidental Dismemberment & Paralysis","") -> Accidental Dismemberment & Paralysis | D36: =D20 -> 150000000 | E36: =IF([1]RFQ!$C$46="Educational Institute",[1]RFQ!D61,"") | G36: =IF([1]RFQ!$C$46="Educational Institute",[1]RFQ!E61,"")
B37: =IF(SUM([1]RFQ!C62:E62)>0,"Permanent Total Disability","") -> Permanent Total Disability | D37: =D20 -> 150000000 | E37: =IF([1]RFQ!$C$46="Educational Institute",[1]RFQ!D62,"") | G37: =IF([1]RFQ!$C$46="Educational Institute",[1]RFQ!E62,"")
B38: =IF(SUM([1]RFQ!C63:E63)>0,"Permanent Partial Disability","") -> Permanent Partial Disability | D38: =D20 -> 150000000 | E38: =IF([1]RFQ!$C$46="Educational Institute",[1]RFQ!D63,"") | G38: =IF([1]RFQ!$C$46="Educational Institute",[1]RFQ!E63,"")
B39: Temporary Total Disability(Per Week SI) | D39: =IF(F6="Basic",'Policy Terms'!C21,IF(F6="Standard",'Policy Terms'!D21,'Policy Terms'!E21)) -> 1% of SI or Rs. 5,000 per week or actual salary, whichever is lower for 104 weeks
D40: =IF([1]RFQ!C65="52 weeks","Temporary Total Disability (Weekly Benefit) - 1% of SI or TTD SI or actual weekly salary for 52 weeks whichever is less","Temporary Total Disability (Weekly Benefit) - 1% of SI or TTD SI or actual weekly salary for 104 weeks whichever is less") -> Temporary Total Disability (Weekly Benefit) - 1% of SI or TTD SI or actual weekly salary for 104 weeks whichever is less | E40: Students and Parents are not covered under TTD benefit
B41: Accident Medical Expenses | D41: =IF(F6="Basic",'Policy Terms'!C22,IF(F6="Standard",'Policy Terms'!D22,'Policy Terms'!E22)) -> 10% of the CSI or 40% of the Admissible Claim or Actuals whichever is less (only if accidental death or disability - PTD/ PPD) | E41: =IF([1]RFQ!C46<>"Educational Institute","",IF(OR([1]RFQ!J29="No",[1]RFQ!D66=""),"Not Covered",IF([1]RFQ!J67<>0,[1]RFQ!J67,IF(OR([1]RFQ!J29="Yes",[1]RFQ!D66<>""),IF(AND([1]RFQ!B67="Yes",[1]RFQ!D67<>""),"Fixed INR "&[1]RFQ!D66&" for IPD with Sublimt of INR "&[1]RFQ!D67&" for OPD or actual claims , whichever is lower.","Fixed INR "&[1]RFQ!D66&" for IPD or actual claims , whichever is lower."))))) | G41: =IF([1]RFQ!C46="Educational Institute", "Medical Expenses of Parents are not Covered.","")
...

Sheet QUOTE LETTER - Client
B1: TATA AIG GENERAL INSURANCE COMPANY LIMITED
B2: QUOTATION AND PROPOSAL FORM GROUP ACCIDENT GUARD POLICY
B3: We have quoted following risk on the basis of information as available / shared with us, it should be same at the time of finalisation of the proposal. Please do inform us in case of any changes in claim information or any other risk factor, as it has implications on appropriate pricing of the risk
B4: Proposer Details
B5: =PROPER("REFERENCE / QUOTE NUMBER") -> Reference / Quote Number | C5: ='QUOTE LETTER - Operations'!C5 -> F/020726-mumbai | E5: Quote Date: | F5: ='QUOTE LETTER - Operations'!F5 -> 46183
B6: =PROPER("NAME OF tHE INSURED") -> Name Of The Insured | C6: ='QUOTE LETTER - Operations'!C6 -> STAY VISTA PRIVATE LIMITED | E6: ='QUOTE LETTER - Operations'!E6 -> Plan Type | F6: ='QUOTE LETTER - Operations'!F6 -> Basic
B7: Risk Inception Date | C7: ='QUOTE LETTER - Operations'!C7 -> 46198 | E7: =[1]RFQ!A8 -> Policy status * | F7: ='QUOTE LETTER - Operations'!F7 -> Fresh
B8: Insured Location | C8: ='QUOTE LETTER - Operations'!C8 -> mumbai | E8: Category | F8: SME
B9: Intermediary Name | C9: ='QUOTE LETTER - Operations'!C9 -> Safetynet Innovations PVT LTD / 2350090000 | E9: Producer Code | F9: ='QUOTE LETTER - Operations'!F9 -> 2350090000
B10: Policy Details
B11: =PROPER("No. OF Lives") -> No. Of Lives | C11: ='QUOTE LETTER - Operations'!C11 -> 488
B12: Type of Policy | C12: ='QUOTE LETTER - Operations'!C12 -> Named
B13: Group Category | C13: ='QUOTE LETTER - Operations'!C13 -> Employer-Employee
B14: =PROPER("BUSINESS DESCRIPTION") -> Business Description | C14: ='QUOTE LETTER - Operations'!C14 -> IT / ITES / BPO / KPO
B15: Description of Insured | C15: ='QUOTE LETTER - Operations'!C15 -> Only Permanent Employees of the company are covered.
B16: =PROPER("AGE BRACKET") -> Age Bracket | C16: ='QUOTE LETTER - Operations'!C16 -> 18 Yrs To 70 Yrs; Only Capital Benefit For Age Above 65 Yrs
B17: Past claim details /Loss Ratio | C17: ='QUOTE LETTER - Operations'!C17 -> 0
B18: Branch | C18: ='QUOTE LETTER - Operations'!C18 -> Mumbai - Peninsula
B19: =[1]RFQ!A28 -> Sum Insured Category (For Employees Only) | C19: =[1]RFQ!B28 -> No of lives | D19: =[1]RFQ!C28 -> Per Person SI | E19: =[1]RFQ!D28 -> Total Sum Insured
B20: =[1]RFQ!A29 -> Category 1 | C20: ='QUOTE LETTER - Operations'!C20 -> 488 | D20: ='QUOTE LETTER - Operations'!D20 -> 150000000 | E20: ='QUOTE LETTER - Operations'!E20 -> 150000000
B21: =[1]RFQ!A30 -> Category 2 | C21: ='QUOTE LETTER - Operations'!C21 -> 0 | D21: ='QUOTE LETTER - Operations'!D21 -> 0 | E21: ='QUOTE LETTER - Operations'!E21 -> 0
B22: =[1]RFQ!A31 -> Category 3 | C22: ='QUOTE LETTER - Operations'!C22 -> 0 | D22: ='QUOTE LETTER - Operations'!D22 -> 0 | E22: ='QUOTE LETTER - Operations'!E22 -> 0
B23: =[1]RFQ!A32 -> Category 4 | C23: ='QUOTE LETTER - Operations'!C23 -> 0 | D23: ='QUOTE LETTER - Operations'!D23 -> 0 | E23: ='QUOTE LETTER - Operations'!E23 -> 0
B24: =[1]RFQ!A33 -> Category 5 | C24: ='QUOTE LETTER - Operations'!C24 -> 0 | D24: ='QUOTE LETTER - Operations'!D24 -> 0 | E24: ='QUOTE LETTER - Operations'!E24 -> 0
B25: =[1]RFQ!A34 -> Category 6 | C25: ='QUOTE LETTER - Operations'!C25 -> 0 | D25: ='QUOTE LETTER - Operations'!D25 -> 0 | E25: ='QUOTE LETTER - Operations'!E25 -> 0
B26: =[1]RFQ!A35 -> Category 7 | C26: ='QUOTE LETTER - Operations'!C26 -> 0 | D26: ='QUOTE LETTER - Operations'!D26 -> 0 | E26: ='QUOTE LETTER - Operations'!E26 -> 0
B27: =[1]RFQ!A36 -> Category 8 | C27: ='QUOTE LETTER - Operations'!C27 -> 0 | D27: ='QUOTE LETTER - Operations'!D27 -> 0 | E27: ='QUOTE LETTER - Operations'!E27 -> 0
B28: =[1]RFQ!A37 -> Category 9 | C28: ='QUOTE LETTER - Operations'!C28 -> 0 | D28: ='QUOTE LETTER - Operations'!D28 -> 0 | E28: ='QUOTE LETTER - Operations'!E28 -> 0
B29: =[1]RFQ!A38 -> Category 10 | C29: ='QUOTE LETTER - Operations'!C29 -> 0 | D29: ='QUOTE LETTER - Operations'!D29 -> 0 | E29: ='QUOTE LETTER - Operations'!E29 -> 0
B30: =[1]RFQ!A39 -> Total | C30: =SUM(C20:C29) -> 488 | D30: =SUM(D20:D29) -> 150000000 | E30: =SUM(E20:E29) -> 150000000
B31: Description of Insured | C31: =[1]RFQ!C57 -> Only Permanent Employees of the company are covered.
B33: =PROPER("BENEFITS OFFERED") -> Benefits Offered | C33: SUM INSURED | D33: =PROPER(IF([1]RFQ!C46="EDUCATIONAL INSTITUTE","STAFF","EMPLOYEES")) -> Employees | E33: =PROPER(IF(C14="EDUCATIONAL INSTITUTE","STUDENT","")) | G33: =PROPER(IF(C14="EDUCATIONAL INSTITUTE","PARENT",""))
B34: Number of Insured | D34: ='QUOTE LETTER - Operations'!D34 -> 488 | E34: =IF([1]RFQ!C46="Educational Institute",IF(D34=0," ",[1]RFQ!D56),"") | G34: =IF([1]RFQ!C46="Educational Institute",IF(D34=0," ",[1]RFQ!E56),"")
B35: =IF(SUM([1]RFQ!C60:E60)>0,"Accidental Death","") -> Accidental Death | D35: ='QUOTE LETTER - Operations'!D35 -> 150000000 | E35: =IF([1]RFQ!$C$46="Educational Institute",[1]RFQ!D60,"") | G35: =IF([1]RFQ!$C$46="Educational Institute",[1]RFQ!E60,"")
B36: =IF(SUM([1]RFQ!C61:E61)>0,"Accidental Dismemberment & Paralysis","") -> Accidental Dismemberment & Paralysis | D36: ='QUOTE LETTER - Operations'!D36 -> 150000000 | E36: =IF([1]RFQ!$C$46="Educational Institute",[1]RFQ!D61,"") | G36: =IF([1]RFQ!$C$46="Educational Institute",[1]RFQ!E61,"")
B37: =IF(SUM([1]RFQ!C62:E62)>0,"Permanent Total Disability","") -> Permanent Total Disability | D37: ='QUOTE LETTER - Operations'!D37 -> 150000000 | E37: =IF([1]RFQ!$C$46="Educational Institute",[1]RFQ!D62,"") | G37: =IF([1]RFQ!$C$46="Educational Institute",[1]RFQ!E62,"")
B38: =IF(SUM([1]RFQ!C63:E63)>0,"Permanent Partial Disability","") -> Permanent Partial Disability | D38: ='QUOTE LETTER - Operations'!D38 -> 150000000 | E38: =IF([1]RFQ!$C$46="Educational Institute",[1]RFQ!D63,"") | G38: =IF([1]RFQ!$C$46="Educational Institute",[1]RFQ!E63,"")
B39: Temporary Total Disability(Per Week SI) | D39: ='QUOTE LETTER - Operations'!D39 -> 1% of SI or Rs. 5,000 per week or actual salary, whichever is lower for 104 weeks
D40: =IF([1]RFQ!C65="52 weeks","Temporary Total Disability (Weekly Benefit) - 1% of SI or TTD SI or actual weekly salary for 52 weeks whichever is less","Temporary Total Disability (Weekly Benefit) - 1% of SI or TTD SI or actual weekly salary for 104 weeks whichever is less") -> Temporary Total Disability (Weekly Benefit) - 1% of SI or TTD SI or actual weekly salary for 104 weeks whichever is less | E40: Students and Parents are not covered under TTD benefit
B41: Accident Medical Expenses | D41: ='QUOTE LETTER - Operations'!D41 -> 10% of the CSI or 40% of the Admissible Claim or Actuals whichever is less (only if accidental death or disability - PTD/ PPD) | E41: =IF([1]RFQ!C46<>"Educational Institute","",IF(OR([1]RFQ!J29="No",[1]RFQ!D66=""),"Not Covered",IF([1]RFQ!J67<>0,[1]RFQ!J67,IF(OR([1]RFQ!J29="Yes",[1]RFQ!D66<>""),IF(AND([1]RFQ!B67="Yes",[1]RFQ!D67<>""),"Fixed INR "&[1]RFQ!D66&" for IPD with Sublimt of INR "&[1]RFQ!D67&" for OPD or actual claims , whichever is lower.","Fixed INR "&[1]RFQ!D66&" for IPD or actual claims , whichever is lower."))))) | G41: =IF([1]RFQ!C46="Educational Institute", "Medical Expenses of Parents are not Covered.","")
...

Sheet Rater
B2: Healthysure x Tata AIG — Group Personal Accident Rater (SME)
B3: Terms valid till 30th Sep 2026 | Min 7 lives, Max 500 lives | Min Premium: INR 3,500 | Only Permanent Employees
B5: SECTION 1 — PREMIUM RATES PER MILLE (excl. GST) | Rates on Death Sum Insured | F5: REFERENCE / QUOTE NUMBER: | G5: =IF(G11="Fresh","F/",IF(G11="Market Rollover","M/",""))&TEXT(TODAY(),"ddmmyy")&"-"&G9 -> F/020726-mumbai
B6: Industry | C6: Basic | D6: Standard | E6: Pro | F6: Quote Date: | G6: 46183
B7: IT / ITES / BPO / KPO | C7: 0.15 | D7: 0.2 | E7: 0.25 | F7: NAME OF THE INSURED: | G7: STAY VISTA PRIVATE LIMITED
B8: Financial Services / Consultancy / Insurance | C8: 0.15 | D8: 0.2 | E8: 0.25 | F8: Risk Inception Date | G8: 46198
B9: Retailers / Trader / Wholesaler | C9: 0.2 | D9: 0.25 | E9: 0.3 | F9: Insured Location | G9: mumbai
B10: Hotel Industry | C10: 0.2 | D10: 0.25 | E10: 0.3 | F10: Intermediary Name | G10: Safetynet Innovations PVT LTD / 2350090000
B11: Manufacturing | C11: 0.2 | D11: 0.3 | E11: 0.32 | F11: Policy status * | G11: Fresh | H11: =IF(G11="Market Rollover", "Kindly Share Exclusive Mandate"," ")
B12: Construction | C12: 0.26 | D12: 0.32 | E12: 0.4 | F12: Type of Policy | G12: Named
F13: No of lives | G13: 488
F14: Group Category | G14: Employer-Employee
B15: * Rates are per mille (‰) on Death Sum Insured. All figures exclude GST. | F15: Description of Insured | G15: Only Permanent Employees of the company are covered.
F16: Age Bracket | G16: =PROPER(IF(AND(G14="EDUCATIONAL INSTITUTE",G15="Only Students of the Educational Institute are covered."),"3 Yrs to 25 Yrs",IF(AND(G14="EDUCATIONAL INSTITUTE",G15<>"Only Students of the Educational Institute are covered."),"3 Yrs to 70 Yrs","18 Yrs TO 70 Yrs; ONLY CAPITAL BENEFIT FOR AGE ABOVE 65 YRS"))) -> 18 Yrs To 70 Yrs; Only Capital Benefit For Age Above 65 Yrs
B17: SECTION 2 — COMMISSION STRUCTURE | F17: Past claim details /Loss Ratio | G17: 0
B18: Component | C18: Basic | D18: Standard | E18: Pro | F18: Branch | G18: Mumbai - Peninsula
B19: Base Commission | C19: 0.075 | D19: 0.075 | E19: 0.075 | F19: Type of Grid | G19: Graded
B20: Base Rewards | C20: 0.075 | D20: 0.075 | E20: 0.075
B21: Base Payout | C21: 0.15 | D21: 0.15 | E21: 0.15
B22: Rewards on Excess Premium | C22: 80:20 | D22: 80:20 | E22: 80:20
B25: SECTION 3 — PREMIUM CALCULATOR (Change highlighted cells)
B26: Flat Sum Insured | F26: Graded Sum Insured
B28: Plan Type | C28: Basic | F28: Plan Type | G28: Basic
B29: Industry | C29: IT / ITES / BPO / KPO | F29: Industry | G29: IT / ITES / BPO / KPO
B31: SI per Employee (INR) | C31: 500000 | F31: Aggregate SI (INR) | G31: 150000000
B32: No. of Employees | C32: =G13 -> 488
B33: Aggregate SI (INR) | C33: =C31*C32 -> 244000000
B35: Per Mille rate - Selling price | C35: 0.15 | E35: =IF(C35<C36,"Check Rate"," ") | F35: Per Mille rate - Selling price | G35: 0.4 | H35: =IF(G35<G36,"Check Rate"," ")
B36: Per Mille rate - Insurance co | C36: =IFERROR(CHOOSE(MATCH(C29,{"IT / ITES / BPO / KPO","Financial Services / Consultancy / Insurance","Retailers / Trader / Wholesaler","Hotel Industry","Manufacturing","Construction"},0),CHOOSE(MATCH(C28,{"Basic","Standard","Pro"},0),0.15,0.2,0.25),CHOOSE(MATCH(C28,{"Basic","Standard","Pro"},0),0.15,0.2,0.25),CHOOSE(MATCH(C28,{"Basic","Standard","Pro"},0),0.2,0.25,0.3),CHOOSE(MATCH(C28,{"Basic","Standard","Pro"},0),0.2,0.25,0.3),CHOOSE(MATCH(C28,{"Basic","Standard","Pro"},0),0.2,0.3,0.32),CHOOSE(MATCH(C28,{"Basic","Standard","Pro"},0),0.26,0.32,0.4)),"?") -> 0.15 | F36: Per Mille rate - Insurance co | G36: =IFERROR(CHOOSE(MATCH(G29,{"IT / ITES / BPO / KPO","Financial Services / Consultancy / Insurance","Retailers / Trader / Wholesaler","Hotel Industry","Manufacturing","Construction"},0),CHOOSE(MATCH(G28,{"Basic","Standard","Pro"},0),0.15,0.2,0.25),CHOOSE(MATCH(G28,{"Basic","Standard","Pro"},0),0.15,0.2,0.25),CHOOSE(MATCH(G28,{"Basic","Standard","Pro"},0),0.2,0.25,0.3),CHOOSE(MATCH(G28,{"Basic","Standard","Pro"},0),0.2,0.25,0.3),CHOOSE(MATCH(G28,{"Basic","Standard","Pro"},0),0.2,0.3,0.32),CHOOSE(MATCH(G28,{"Basic","Standard","Pro"},0),0.26,0.32,0.4)),"?") -> 0.15
B38: Gross Premium | C38: =C33*C35/1000 -> 36600 | F38: Gross Premium | G38: =MAX(3500,G31*G35/1000) -> 60000 | I38: =G31*G35/1000 -> 60000
B40: Base Commission 7.5% | C40: =C38*0.075 -> 2745 | F40: Base Commission 7.5% | G40: =G38*0.075 -> 4500
B41: Base Rewards 7.5% | C41: =C38*0.075 -> 2745 | F41: Base Rewards 7.5% | G41: =G38*0.075 -> 4500
B42: Rewards on excess premium collected | C42: =C33*(C35-C36)*0.65/1000 -> 0 | F42: Rewards on excess premium collected | G42: =G31*(G35-G36)*0.65/1000 -> 24375
B43: Total Earnings | C43: =SUM(C40:C42) -> 5490 | F43: Total Earnings | G43: =SUM(G40:G42) -> 33375
B45: Base Commission % | C45: =C40/C38 -> 0.075 | F45: Base Commission % | G45: =G40/G38 -> 0.075
B46: Total Rewards % | C46: =(C41+C42)/C38 -> 0.075 | F46: Base Rewards % | G46: =(G41+G42)/G38 -> 0.48125
B47: Total Earnings % | C47: =SUM(C45:C46) -> 0.15 | F47: Total Earnings % | G47: =SUM(G45:G46) -> 0.55625
B52: LEGEND
B53: White — User Input (change these)
B54: Green — Calculated (do not edit)

Sheet Policy Terms
B1: Group Accident Guard Product - SME (Terms are valid till 30th Sep'26 only)
B2: Features | C2: Basic | D2: Standard | E2: Pro
B3: Claims | C3: Nil | D3: Nil | E3: Nil
B4: Number of Lives | C4: Min 7 | D4: Min 7 | E4: Min 7
C5: Max 500 | D5: Max 500 | E5: Max 500
B6: Minimum Premium requirement | C6: INR 3500 | D6: INR 3500 | E6: INR 3500
B7: Description of Insured | C7: Only Permanent Employees of the company are covered. | D7: Only Permanent Employees of the company are covered. | E7: Only Permanent Employees of the company are covered.
B8: SI Type | C8: Flat | D8: Flat | E8: Flat
B9: Max SI per person | C9: INR 1Cr | D9: INR 1Cr | E9: INR 1Cr
B10: Industry of Insured | C10: Rates per mille on death sum-insured | D10: Rates per mille on death sum-insured | E10: Rates per mille on death sum-insured
B11: IT / ITES / BPO KPO | C11: 0.15 | D11: 0.2 | E11: 0.25
B12: Manufacturing | C12: 0.2 | D12: 0.3 | E12: 0.32
B13: Financial Services / Consultancy / Insurance | C13: 0.15 | D13: 0.2 | E13: 0.25
B14: Construction | C14: 0.26 | D14: 0.32 | E14: 0.4
B15: Retailers / Trader / Wholesaler | C15: 0.2 | D15: 0.25 | E15: 0.3
B16: Hotel Industry | C16: 0.2 | D16: 0.25 | E16: 0.3
B17: Coverages :
B18: Accidental Death | C18: 100% of SI | D18: 100% of SI | E18: 100% of SI
B19: Permanent Total Disablement | C19: 100% of SI | D19: 100% of SI | E19: 100% of SI
B20: Permanent Partial Disablement | C20: Up to 100% of SI based on extent of disability | D20: Up to 100% of SI based on extent of disability | E20: Up to 100% of SI based on extent of disability
B21: Temporary Total Disablement (if patient confined to bed due to temporary and total inability to engage in any occupation or any activity) | C21: 1% of SI or Rs. 5,000 per week or actual salary, whichever is lower for 104 weeks | D21: 1% of SI or Rs. 5,000 per week or actual salary, whichever is lower for 104 weeks | E21: 1% of SI or Rs. 10,000 per week or actual salary, whichever is lower for 104 weeks
B22: Accidental Hospitalization - Medex IPD | C22: 10% of the CSI or 40% of the Admissible Claim or Actuals whichever is less (only if accidental death or disability - PTD/ PPD) | D22: Fixed INR 1,00,000 or Actuals whichever is lower. | E22: Fixed INR 1,00,000 or Actuals whichever is lower.
B23: Additional Benefits | C23: Children Education Benefit- 10% of SI upto Rs. 5000 per child (max 2 children upto 25 years of age) Compassionate Visit - 10% SI upto Rs. 25,000 Funeral Expenses - 2.5% of SI upto Rs. 2500 Transportation of Dead Body - 2.5% of SI upto Rs.2500 | D23: Children Education Benefit- 10% of SI upto Rs. 5000 per child (max 2 children upto 25 years of age) Compassionate Visit - 10% SI upto Rs. 25,000 Funeral Expenses - 2.5% of SI upto Rs. 5000 Transportation of Dead Body - 2.5% of SI upto Rs.5000 Lifestyle modification - 10% SI upto Rs. 10,000 | E23: Children Education Benefit- Upto Rs. 10,000 per child (max 2 children upto 25 years of age) Compassionate Visit - 10% SI upto Rs. 25,000 Funeral Expenses - 5% of SI upto Rs. 10,000 Transportation of Dead Body - 5% of SI upto Rs.10,000 Lifestyle modification - 10% SI upto Rs. 25,000
B24: Ambulance Charges | C24: NA | D24: 5000 | E24: 5000
B27: Education Benefit | C27: 10% of SI upto Rs. 5000 per child (max 2 children upto 25 years of age) | D27: 10% of SI upto Rs. 5000 per child (max 2 children upto 25 years of age) | E27: Upto Rs. 10,000 per child (max 2 children upto 25 years of age)
B28: Compassionate Visit | C28: 10% SI upto Rs. 25,000 | D28: 10% SI upto Rs. 25,000 | E28: 10% SI upto Rs. 25,000
B29: Funeral Expenses | C29: 2.5% of SI upto Rs. 2500 | D29: 2.5% of SI upto Rs. 5000 | E29: 5% of SI upto Rs. 10,000
B30: Transportation of dead body | C30: 2.5% of SI upto Rs.2500 | D30: 2.5% of SI upto Rs.5000 | E30: 5% of SI upto Rs.10,000
B31: Lifestyle modification | C31: NA | D31: 10% SI upto Rs. 10,000 | E31: 10% SI upto Rs. 25,000

Sheet Commissions
B3: Base Commission | C3: 0.075 | D3: 0.075 | E3: 0.075
B4: Rewards | C4: 0.075 | D4: 0.075 | E4: 0.075
B5: Rewards on Excess Premium | C5: 80:20 | D5: 80:20 | E5: 80:20

Sheet Decline List
A2: Please find below list of Decline risk categories.
A3: 1 | B3: Defence
A4: 2 | B4: Police
A5: 3 | B5: Mining (open & closed)
A6: 4 | B6: Lawyers & Legal
A7: 5 | B7: Advertisement / Media / Entertainment
A8: 6 | B8: Offshore Workers
A9: 7 | B9: Coal & Fossil Fuels
A10: 8 | B10: Professional or Semi Professional Sports
A11: 9 | B11: Employed to work above the height of 10 mtrs from the ground
A12: 10 | B12: Commercial drivers
A13: 11 | B13: Lives involved in electrical wires/ Working on active transmission lives
A14: 12 | B14: Religious / Social Sector (Pilgrims etc)
