Workbook
Name AdditionsandDeletions: 'GHI DB'!$BG$3:$BH$3
Name AYUSHTreatments: 'GHI DB'!$BA$3:$BB$3
Name CashlessAuthorizationTAT: 'GHI DB'!$BO$3
Name CashlessNetwork: 'GHI DB'!$W$3
Name ClaimsIntermediary: 'GHI DB'!$Y$3
Name CoPay: 'GHI DB'!$M$3:$R$3
Name CorporateBuffer: 'GHI DB'!$S$3:$T$3
Name COVID19Coverage: 'GHI DB'!$AC$3
Name DayCareTreatments: 'GHI DB'!$AA$3
Name DentalCoverage: 'GHI DB'!$AM$3
Name DiseaseCapping: 'GHI DB'!$AB$3
Name DoctorTeleconsultations: 'GHI DB'!$AG$3
Name DomicillaryHospitalization: 'GHI DB'!$AD$3
Name EmergencyAirAmbulance: 'GHI DB'!$AW$3:$AW$3
Name EmergencyAmbulance: 'GHI DB'!$AV$3
Name FamilyDefinition: 'GHI DB'!$C$3:$F$3
Name features: 'GHI DB'!$B$1:$BS$1
Name GHI_Quotes: 'High Level Quotes - Working'!$B$3:$N$15
Name GPA_features: 'GPA DB'!$D$3:$O$3
Name GPA_Insurers: 'GPA DB'!$A$4:$A$9
Name GPA_number_of_lives_expiring: 'High Level Quotes - Working'!$T$22
Name GPA_opt1_number_of_employees_expiring: 'High Level Quotes - Working'!$T$22
Name GPA_opt1_number_of_employees_renewal: 'High Level Quotes - Working'!$R$22
Name GPA_opt1_number_of_lives_renewal: 'High Level Quotes - Working'!$S$22
Name GPA_opt2_number_of_employees_expiring: 'High Level Quotes - Working'!$T$24
Name GPA_opt2_number_of_employees_renewal: 'High Level Quotes - Working'!$R$24
Name GPA_opt2_number_of_lives_renewal: 'High Level Quotes - Working'!$S$24
Name GPA_Quotes: 'High Level Quotes - Working'!$B$18:$N$25
Name GPA_Quotes: 'High Level Quotes - Slide 1'!$B$13:$N$18
Name GTLI_Features: 'GTLI DB'!$D$7:$J$7
Name GTLI_number_of_employees_expiring: 'High Level Quotes - Working'!$T$32
Name GTLI_number_of_lives_expiring: 'High Level Quotes - Working'!$T$32
Name GTLI_opt1_number_of_employees_renewal: 'High Level Quotes - Working'!$R$32
Name GTLI_opt2_number_of_employees_renewal: 'High Level Quotes - Working'!$R$34
Name GTLI_Quotes: 'High Level Quotes - Working'!$B$28:$N$35
Name GTLI_Quotes: 'High Level Quotes - Slide 1'!$B$22:$N$27
Name HealthCheckups: 'GHI DB'!$AJ$3
Name InitialWaitingPeriod: 'GHI DB'!$AS$3
Name InpatientHospitalization: 'GHI DB'!$Z$3
Name Know_Your_Insurers: 'Policy & Technical Features'!$Q$27:$Z$42
Name Know_Your_Insurers: 'Policy & Technical Features - o'!$Q$26:$Z$41
Name LasikEyeSurgery: 'GHI DB'!$BE$3
Name Logo: 'GHI DB'!$B$3
Name MaternityCover: 'GHI DB'!$AN$3:$AO$3
Name MaternityWaitingPeriod: 'GHI DB'!$AP$3:$AQ$3
Name MedicinesDelivery: 'GHI DB'!$AL$3
Name MidtermAdditionofDependents: 'GHI DB'!$BK$3:$BL$3
Name Midtermadditionofparents: 'GHI DB'!$BM$3:$BN$3
Name MidtermIncreaseinSumInsured: 'GHI DB'!$BI$3:$BJ$3
Name ModernTreatmentsandRoboticSurgeries: 'GHI DB'!$AX$3
Name number_of_employees_expiring: 'High Level Quotes - Working'!$T$6
Name number_of_employees_expiring: 'High Level Quotes - Slide 1'!$U$6
Name number_of_lives_expiring: 'High Level Quotes - Working'!$U$6
Name number_of_lives_expiring: 'High Level Quotes - Slide 1'!$V$6
Name opt1_number_of_employees_renewal: 'High Level Quotes - Working'!$R$6
Name opt1_number_of_employees_renewal: 'High Level Quotes - Slide 1'!$R$6
Name opt1_number_of_lives_renewal: 'High Level Quotes - Working'!$S$6
Name opt1_number_of_lives_renewal: 'High Level Quotes - Slide 1'!$S$6
Name opt2_number_of_employees_renewal: 'High Level Quotes - Working'!$R$8
Name opt2_number_of_employees_renewal: 'High Level Quotes - Slide 1'!$R$7

Sheet High Level Quotes - Slide 1
D2: Group Health Insurance | P2: File Path of Proposal Deck | AH2: =D2 -> Group Health Insurance
D3: Options for Renewal | M3: Previous Policy | P3: C:\Users\shali\Downloads\Key Policy Features\Product Deck Editable Slides (In Use).pptx | AH3: Options for Renewal | AQ3: Incumbent Policy
D4: ='Policy & Technical Features - o'!F6 -> Manipal Cigna Standard Rater | G4: ='Policy & Technical Features - o'!H6 -> SBI General | J4: ='Policy & Technical Features - o'!J6 -> Manipal Cigna | M4: ='Policy & Technical Features - o'!L6 -> IFFCO Tokio | P4: Our Options | R4: No. of Employees (renewal) | S4: No. of Lives (renewal) | T4: Premium (excl GST) | U4: No. of Employees (expiring policy) | V4: No. of Lives (expiring policy) | AF4: Our Options | AH4: =D4 -> Manipal Cigna Standard Rater | AK4: =G4 -> SBI General | AN4: =J4 -> Manipal Cigna | AQ4: =M4 -> IFFCO Tokio
D5: Total Premium (excl. GST) | E5: Premium per Life | G5: Total Premium (excl. GST) | H5: Premium per Life | J5: Total Premium (excl. GST) | K5: Premium per Life | M5: Total Premium (excl. GST) | N5: Premium per Life | AH5: Total Premium (excl. GST) | AI5: Premium per Life | AK5: Total Premium (excl. GST) | AL5: Premium per Life | AN5: Total Premium (excl. GST) | AO5: Premium per Life | AQ5: Total Premium (excl. GST) | AR5: Premium per Life
B6: I. Expiring Terms (SI: 2 L) | D6: =CONCATENATE(TRUNC(T6,0), CHAR(10), "(", S6, " lives)") -> 2000000 (450 lives) | E6: =T6/opt1_number_of_lives_renewal -> 4444.4444 | G6: 20,00,000 | J6: 20,00,000 | M6: 20,00,000 | P6: =B6 -> I. Expiring Terms (SI: 2 L) | R6: 300 | S6: 450 | T6: 2000000 | U6: 200 | V6: 300 | AF6: I. Expiring Terms (SI: 2 L) | AH6: =D6 -> 2000000 (450 lives) | AI6: =AH6/opt1_number_of_lives_renewal -> #VALUE! | AK6: =G6 -> 20,00,000 | AL6: =AK6/opt1_number_of_lives_renewal -> #VALUE! | AN6: =J6 -> 20,00,000 | AO6: =AN6/opt1_number_of_lives_renewal -> #VALUE! | AQ6: =M6 -> 20,00,000 | AR6: =AQ6/number_of_lives_expiring -> #VALUE!
B7: II. ESC with 0% Co-Pay (SI : 5 L) | D7: =CONCATENATE(TRUNC(T7,0), CHAR(10), "(", S7, " lives)") -> 2500000 (450 lives) | E7: =T7/opt1_number_of_lives_renewal -> 5555.5556 | G7: 30,00,000 | J7: 30,00,000 | P7: =B7 -> II. ESC with 0% Co-Pay (SI : 5 L) | R7: =opt1_number_of_employees_renewal -> 300 | S7: 450 | T7: 2500000 | AF7: II. ESC with 0% Co-Pay (SI : 5 L) | AH7: =D7 -> 2500000 (450 lives) | AI7: =AH7/opt2_number_of_lives_renewal -> #VALUE! | AK7: =G7 -> 30,00,000 | AL7: =AK7/opt2_number_of_lives_renewal -> #VALUE! | AN7: =J7 -> 30,00,000 | AO7: =AN7/opt2_number_of_lives_renewal -> #VALUE!
B8: III. ESCP with 0% Co-Pay (SI : 3 L) | D8: =CONCATENATE(TRUNC(T8,0), CHAR(10), "(", S8, " lives)") -> 3000000 (600 lives) | E8: =T8/opt1_number_of_lives_renewal -> 6666.6667 | G8: 40,00,000 | J8: 40,00,000 | P8: =B8 -> III. ESCP with 0% Co-Pay (SI : 3 L) | R8: =opt1_number_of_employees_renewal -> 300 | S8: 600 | T8: 3000000 | AF8: III. ESCP with 0% Co-Pay (SI : 3 L) | AH8: =D8 -> 3000000 (600 lives) | AI8: =AH8/opt3_number_of_lives_renewal -> #VALUE! | AK8: =G8 -> 40,00,000 | AL8: =AK8/opt3_number_of_lives_renewal -> #VALUE! | AN8: =J8 -> 40,00,000 | AO8: =AN8/opt3_number_of_lives_renewal -> #VALUE!
B9: IV. ESCP with 0% Co-Pay (SI : 5 L) | D9: =CONCATENATE(TRUNC(T9,0), CHAR(10), "(", S9, " lives)") -> 4000000 (600 lives) | E9: =T9/opt1_number_of_lives_renewal -> 8888.8889 | G9: 50,00,000 | J9: 50,00,000 | P9: =B9 -> IV. ESCP with 0% Co-Pay (SI : 5 L) | R9: =opt1_number_of_employees_renewal -> 300 | S9: 600 | T9: 4000000 | AF9: IV. ESCP with 0% Co-Pay (SI : 5 L) | AH9: =D9 -> 4000000 (600 lives) | AI9: =AH9/opt4_number_of_lives_renewal -> #VALUE! | AK9: =G9 -> 50,00,000 | AL9: =AK9/opt4_number_of_lives_renewal -> #VALUE! | AN9: =J9 -> 50,00,000 | AO9: =AN9/opt4_number_of_lives_renewal -> #VALUE!
B10: V. ESCP with 0% Co-Pay (SI : 5 L) | D10: =CONCATENATE(TRUNC(T10,0), CHAR(10), "(", S10, " lives)") -> 5000000 (600 lives) | E10: =T10/opt1_number_of_lives_renewal -> 11111.111 | G10: 60,00,000 | J10: 60,00,000 | P10: =B10 -> V. ESCP with 0% Co-Pay (SI : 5 L) | R10: =opt1_number_of_employees_renewal -> 300 | S10: 600 | T10: 5000000 | AF10: V. ESCP with 0% Co-Pay (SI : 5 L) | AH10: =D10 -> 5000000 (600 lives) | AI10: =AH10/opt5_number_of_lives_renewal -> #VALUE! | AK10: =G10 -> 60,00,000 | AL10: =AK10/opt5_number_of_lives_renewal -> #VALUE! | AN10: =J10 -> 60,00,000 | AO10: =AN10/opt5_number_of_lives_renewal -> #VALUE!
D13: Group Personal Accident Insurance | AH13: Group Personal Accident Insurance
D14: Options for Renewal | M14: Incumbent Insurer | AH14: Options for Renewal | AQ14: Incumbent Policy
B15: Our Options | D15: Insurer 1 | G15: Insurer 2 | J15: Insurer 3 | M15: Insurer 4 | AF15: Our Options | AH15: Insurer 1 | AK15: Insurer 2 | AN15: Insurer 3 | AQ15: Insurer 4
D16: Total Premium (excl. GST) | E16: Premium per Employee | G16: Total Premium (excl. GST) | H16: Premium per Employee | J16: Total Premium (excl. GST) | K16: Premium per Employee | M16: Total Premium (excl. GST) | N16: Premium per Employee | AH16: Total Premium (excl. GST) | AI16: Premium per Employee | AK16: Total Premium (excl. GST) | AL16: Premium per Employee | AN16: Total Premium (excl. GST) | AO16: Premium per Employee | AQ16: Total Premium (excl. GST) | AR16: Premium per Employee
B17: I. Expiring Terms (SI: 10 L) | D17: 2,00,000 | G17: 2,00,000 | J17: 2,00,000 | M17: 2,00,000 | N17: =M17/number_of_employees_expiring -> #VALUE! | AF17: I. Expiring Terms (SI: 10 L) | AH17: 2,00,000 | AI17: =AH17/opt1_number_of_employees_renewal -> #VALUE! | AK17: 2,00,000 | AL17: =AK17/opt1_number_of_employees_renewal -> #VALUE! | AN17: 2,00,000 | AO17: =AN17/opt1_number_of_employees_renewal -> #VALUE! | AQ17: 2,00,000 | AR17: =AQ17/number_of_employees_expiring -> #VALUE!
B18: II. SI: 25 L | D18: 4,00,000 | G18: 4,00,000 | J18: 4,00,000 | AF18: II. SI: 25 L | AH18: 4,00,000 | AI18: =AH18/opt1_number_of_employees_renewal -> #VALUE! | AK18: 4,00,000 | AL18: =AK18/opt1_number_of_employees_renewal -> #VALUE! | AN18: 4,00,000 | AO18: =AN18/opt1_number_of_employees_renewal -> #VALUE!
D22: Group Term Life Insurance | AH22: Group Term Life Insurance
D23: Options for Renewal | M23: Incumbent Policy | AH23: Options for Renewal | AQ23: Incumbent Policy
B24: Our Options | D24: Insurer 1 | G24: Insurer 2 | J24: Insurer 3 | M24: Insurer 4 | AF24: Our Options | AH24: Insurer 1 | AK24: Insurer 2 | AN24: Insurer 3 | AQ24: Insurer 4
D25: Total Premium (excl. GST) | E25: Premium per Employee | G25: Total Premium (excl. GST) | H25: Premium per Employee | J25: Total Premium (excl. GST) | K25: Premium per Employee | M25: Total Premium (excl. GST) | N25: Premium per Employee | AH25: Total Premium (excl. GST) | AI25: Premium per Employee | AK25: Total Premium (excl. GST) | AL25: Premium per Employee | AN25: Total Premium (excl. GST) | AO25: Premium per Employee | AQ25: Total Premium (excl. GST) | AR25: Premium per Employee
B26: I. Expiring Terms (SI: 10 L) | D26: 4,00,000 | G26: 4,00,000 | J26: 4,00,000 | M26: 4,00,000 | N26: =M26/number_of_employees_expiring -> #VALUE! | AF26: I. Expiring Terms (SI: 10 L) | AH26: 4,00,000 | AI26: =AH26/opt1_number_of_employees_renewal -> #VALUE! | AK26: 4,00,000 | AL26: =AK26/opt1_number_of_employees_renewal -> #VALUE! | AN26: 4,00,000 | AO26: =AN26/opt1_number_of_employees_renewal -> #VALUE! | AQ26: 4,00,000 | AR26: =AQ26/number_of_employees_expiring -> #VALUE!
B27: II. SI: 25 L | D27: 8,00,000 | G27: 8,00,000 | J27: 8,00,000 | AF27: II. SI: 25 L | AH27: 8,00,000 | AI27: =AH27/opt1_number_of_employees_renewal -> #VALUE! | AK27: 8,00,000 | AL27: =AK27/opt1_number_of_employees_renewal -> #VALUE! | AN27: 8,00,000 | AO27: =AN27/opt1_number_of_employees_renewal -> #VALUE!

Sheet SOP
B2: DISCLAIMER
B3: =B1+1 -> 1 | C3: Do not change any formula in the Excel file or add/delete/hide/unhide/shift any sheets till you complete running the automation and are satisfied with the output.
B4: =B3+1 -> 2 | C4: Do not meddle with any of the data validation/macros/formatting in this Excel file.
B5: =B4+1 -> 3 | C5: Do not change the order of the slides in the Proposal Deck before running the automation. You can change the order of slides only on completion of the steps in the SOP mentioned below.
B6: =B5+1 -> 4 | C6: Similarly, do not add/delete any slides in the proposal deck before you complete the SOP mentioned below.
B9: SOP for running automation for Quotes, Policy Features, and Technical Parameters.
B10: 1 | C10: Before beginning, move the Template folder containing this file and the Proposal Deck to the Downloads folder of your PC. If this is not done at this step, close this file, move the folder to Downloads and resume with your work.
B11: =B10+1 -> 2 | C11: In the 'Inputs' tab, enter the following things (All the cells highlighted in blue need to be filled): 1. Name of the client (brand name) - Cell B5 2. File Path of the Proposal Deck - Cell B9 - Go to the Folder containing the Proposal Deck (in Downloads) --> Click on Proposal Deck --> Ctrl+Shift+C (this will copy the file path) --> Paste this in cell B9 3. The top 3 renewal insurers for GHI + expiring insurer in cells B14 to E14. 4. The number of employees and lives in the expiring policy - Cells F25 and G25 5. The various policy options for GHI in cells B25 to B34 along with the number of lives in each plan - Use short forms like ESC, ESCP, SI, etc. as per your convenience 6. The premiums (excluding GST) for each of the options in the area alongside the table 7. Repeat steps 4 to 6 for GPA and GTLI (if applicable)
B12: =B11+1 -> 3 | C12: Make copies of GHI Policy Features (Option 1) for as many options as you're giving the client. You can also rename with sheet with the option. For example: GHI Policy Features (ESC - 5 Lakh SI)
B13: =B12+1 -> 4 | C13: Enter the following things in each of these sheets: Policy Period, Net Premium for each insurer, Sum Insured for each option, Number of Lives (for the copied sheets)
B14: =B13+1 -> 5 | C14: Now, in each of the sheets of 'GHI Policy Features), as per the family definition, delete rows all/any of 17, 18, or 19 from the table if required. For example, if it is an Employee only policy, delete all 3 rows. If it is an ESC policy, delete only row 19. Recolour the red cells to the color of the cells above it (light grey)
B15: =B14+1 -> 6 | C15: Verify whether the rest if the features populated in the sheet are as desired by the client.
B16: =B15+1 -> 7 | C16: Now, go to the 'Policy & Technical Features' tab and start selecting the features which you want to show in the Policy Features comparison.
B17: =B16+1 -> 8 | C17: For Family Definition, select the appropriate option as desired by the GM/Client
B18: =B17+1 -> 9 | C18: For other features, following is the methodology: a. First, select the feature in column B from the dropdown list (Use Alt+Down Arrow key to open the dropdown) b. Based on what you select in Column B, you will get option/benefit in the dropdown list in Column D. Select the desired option/benefit. The cells from Column F to L will get populated automatically based on the insurers chosen as and when you select the desired feature to be shown. Please note that you need to select only 9 features apart from Family Definition which you would like to display in the Proposal Deck.
B19: =B18+1 -> 10 | C19: The Technical Parameters (Insurer Credentials) will automatically get populated.
B20: =B19+1 -> 11 | C20: Once the 'GHI Policy Features' and 'Know your Insurer - Credentials' tabs are final, select all the sheets which you want to send to the client (Policy Features of all options + Know your Insurers), click on the '…' button on the 'GHI Policy Features' tab. By doing this, a new Excel file with the selected tabs will be created to be sent to the client. The file will be saved in the same folder as this Excel file.
B21: =B20+1 -> 12 | C21: Open the new Excel file from the folder bearing the name 'Client GHI Quotes.' On every tab in that workbook, do the following: Ctrl+A Ctrl+C Ctrl+Alt+V Press Enter Next, delete the content from cell A1 of the 'Know your Insurer - Credentials' tab in the new workbook. Delete the button on the 'GHI Policy Features (Option 1)' sheet
B22: =B21+1 -> 13 | C22: Go to the tab 'High Level Quotes - Working' and verify whether all the details are numbers have been populated as required. Once you have verified everything: Click on the button: Send GHI Quotes to Proposal Deck Click on the button: Send GPA Quotes to Proposal Deck Click on the button: Send GTLI Quotes to Proposal Deck
... B27: =B26+1 -> 18 | C27: Once everything is final, save all the files, and transfer the files to the relevant client's folder on Sharepoint

Sheet Inputs
B1: Date
B2: 45177
B4: Name of the Client
B5: Bandana Gupta Class
B8: Proposal Deck File Path
B9: C:\Users\shali\Downloads\ABCD\Healthysure Proposal Deck.pptx
B12: GHI Insurer Options
B13: PROPOSED INSURERS | E13: PREVIOUS INSURER
B14: Manipal Cigna Standard Rater | C14: SBI General | D14: Manipal Cigna | E14: IFFCO Tokio
B19: GHI Quotes
B21: File Path of Proposal Deck | I21: Options for Renewal | L21: Previous Policy
I22: =B14 -> Manipal Cigna Standard Rater | J22: =C14 -> SBI General | K22: =D14 -> Manipal Cigna | L22: =E14 -> IFFCO Tokio
B23: Proposed Options | D23: No. of Employees (renewal) | E23: No. of Lives (renewal) | F23: No. of Employees (expiring policy) | G23: No. of Lives (expiring policy) | I23: Total Premium (₹) | J23: Total Premium (₹) | K23: Total Premium (₹) | L23: Total Premium (₹)
B25: I. ESCP with 10% Co-pay (SI: 10 L) | D25: 6 | E25: 6 | F25: 20 | G25: 30 | I25: 4,55,316 | J25: 5,19,638 | K25: 5,26,249 | L25: 3,13,559
B27: II. ESC with 0% Co-Pay (SI : 5 L) | D27: =D25 -> 6 | E27: z | F27: - | I27: 25,00,000 | J27: 30,00,000 | K27: 30,00,000 | L27: -
B29: III. ESCP with 0% Co-Pay (SI : 3 L) | D29: =D25 -> 6 | E29: 800 | I29: 30,00,000 | J29: 40,00,000 | K29: 40,00,000 | L29: -
B31: IV. ESCP with 0% Co-Pay (SI : 5 L) | D31: =D25 -> 6 | E31: 800 | I31: 50,00,000 | J31: 50,00,000 | K31: 50,00,000 | L31: -
B33: V. ESCP with 0% Co-Pay (SI : 5 L) | D33: =D25 -> 6 | E33: 800 | I33: 60,00,000 | J33: 60,00,000 | K33: 60,00,000 | L33: -
B37: GPA Insurer Options
B38: PROPOSED INSURERS | E38: PREVIOUS INSURER
B39: Magma HDI (Basic Plan) - NEE Group | C39: Magma HDI (Pro Plan) - NEE Group | D39: Go Digit (Pro Plan) | E39: IFFCO Tokio ( Pro Plan)
B41: GPA Quotes
B43: Proposed Options | D43: No. of Employees (renewal) | F43: No. of Employees (expiring policy) | I43: =B39 -> Magma HDI (Basic Plan) - NEE Group | J43: =C39 -> Magma HDI (Pro Plan) - NEE Group | K43: =D39 -> Go Digit (Pro Plan) | L43: =E39 -> IFFCO Tokio ( Pro Plan)
I44: Total Premium (₹) | J44: Total Premium (₹) | K44: Total Premium (₹) | L44: Total Premium (₹)
B45: I. Expiring Terms (SI: 10 L) | D45: 30 | F45: 20 | I45: 20,00,000 | J45: 20,00,000 | K45: 20,00,000 | L45: 20,00,000
B47: II. SI: 25 L | D47: =D45 -> 30 | F47: - | I47: 39,00,000 | J47: 30,00,000 | K47: 30,00,000 | L47: -
B51: GTLI Insurer Options
B52: PROPOSED INSURERS | E52: PREVIOUS INSURER
B53: CALI (Exclusive) | C53: CALI (Exclusive) | D53: HDFC Life | E53: Pramerica Life
B55: GTLI Quotes
B57: Proposed Options | D57: No. of Employees (renewal) | F57: No. of Employees (expiring policy) | I57: =B53 -> CALI (Exclusive) | J57: =C53 -> CALI (Exclusive) | K57: =D53 -> HDFC Life | L57: =E53 -> Pramerica Life
I58: Total Premium (₹) | J58: Total Premium (₹) | K58: Total Premium (₹) | L58: Total Premium (₹)
B59: I. Expiring Terms (SI: 10 L) | D59: 300 | F59: 150 | I59: 25,00,000 | J59: 20,00,000 | K59: 20,00,000 | L59: 20,00,000
B61: II. SI: 25 L | D61: =D59 -> 300 | F61: - | I61: 35,00,000 | J61: 30,00,000 | K61: 30,00,000 | L61: -
B68: OPD Options
B69: PROPOSED INSURERS
B70: Visit SI - 5000 | C70: Even SI - 5000 | D70: Even SI - 5000

Sheet Premium Breakdown
B2: Premium of Recommended Option: | M2: Breakdown of Premium per Life
B3: 300 | D3: x | F3: 6000 | H3: = | J3: 11800000 | M3: 200 | N3: + | O3: 50 | P3: + | Q3: 50
B4: Premium per Life | F4: Number of Lives | J4: Total Premium | M4: Claims per life | O4: Proposed Terms Impact | Q4: Inflation and Buffer

Sheet High Level Quotes - Working
G1: ₹
P2: File Path of Proposal Deck
D3: Options for Renewal | M3: Previous Policy | P3: =Inputs!B9 -> C:\Users\shali\Downloads\ABCD\Healthysure Proposal Deck.pptx
D4: ='GHI Features (Option 1)'!G8 -> HDFC Ergo | G4: ='GHI Features (Option 1)'!H8 -> Manipal Cigna (Gig Exclusive) | J4: ='GHI Features (Option 1)'!I8 -> Manipal Cigna (SME Exclusive) | M4: ='GHI Features (Option 1)'!J8 -> Care Health | P4: Proposed Options | R4: No. of Employees (renewal) | S4: No. of Lives (renewal) | T4: No. of Employees (expiring policy) | U4: No. of Lives (expiring policy)
D5: Total Premium (₹) | E5: Avg. Premium/Life | G5: Total Premium (₹) | H5: Avg. Premium/Life | J5: Total Premium (₹) | K5: Avg. Premium/Life | M5: Total Premium (₹) | N5: Avg. Premium/Life
B6: =Inputs!B25 -> I. ESCP with 10% Co-pay (SI: 10 L) | D6: =Inputs!I25 | E6: =D6/opt1_number_of_lives_renewal -> #VALUE! | G6: =Inputs!J25 -> 5,19,638 | H6: =G6/opt1_number_of_lives_renewal -> #VALUE! | J6: =Inputs!K25 -> 5,26,249 | K6: =J6/opt1_number_of_lives_renewal -> #VALUE! | M6: =Inputs!L25 -> 3,13,559 | N6: =M6/number_of_lives_expiring -> #VALUE! | P6: =Inputs!B25 -> I. ESCP with 10% Co-pay (SI: 10 L) | R6: =Inputs!D25 -> 6 | S6: =Inputs!E25 -> 6 | T6: =Inputs!F25 -> 20 | U6: =Inputs!G25 -> 30
D7: =CONCATENATE("(", opt1_number_of_lives_renewal, " lives)") -> (6 lives) | G7: =CONCATENATE("(", opt1_number_of_lives_renewal, " lives)") -> (6 lives) | J7: =CONCATENATE("(", opt1_number_of_lives_renewal, " lives)") -> (6 lives) | M7: =CONCATENATE("(", number_of_lives_expiring, " lives)") -> (30 lives)
B8: =Inputs!B27 -> II. ESC with 0% Co-Pay (SI : 5 L) | D8: =Inputs!I27 -> 25,00,000 | E8: =D8/opt2_number_of_lives_renewal -> #VALUE! | G8: =Inputs!J27 -> 30,00,000 | H8: =G8/opt2_number_of_lives_renewal -> #VALUE! | J8: =Inputs!K27 -> 30,00,000 | K8: =J8/opt2_number_of_lives_renewal -> #VALUE! | M8: - | N8: - | P8: =Inputs!B27 -> II. ESC with 0% Co-Pay (SI : 5 L) | R8: =Inputs!D27 -> 6 | S8: =Inputs!E27 -> z | T8: -
D9: =CONCATENATE("(", opt2_number_of_lives_renewal, " lives)") -> (z lives) | G9: =CONCATENATE("(", opt2_number_of_lives_renewal, " lives)") -> (z lives) | J9: =CONCATENATE("(", opt2_number_of_lives_renewal, " lives)") -> (z lives)
B10: =Inputs!B29 -> III. ESCP with 0% Co-Pay (SI : 3 L) | D10: =Inputs!I29 -> 30,00,000 | E10: =D10/opt3_number_of_lives_renewal -> #VALUE! | G10: =Inputs!J29 -> 40,00,000 | H10: =G10/opt3_number_of_lives_renewal -> #VALUE! | J10: =Inputs!K29 -> 40,00,000 | K10: =J10/opt3_number_of_lives_renewal -> #VALUE! | M10: - | N10: - | P10: =Inputs!B29 -> III. ESCP with 0% Co-Pay (SI : 3 L) | R10: =Inputs!D29 -> 6 | S10: =Inputs!E29 -> 800
D11: =CONCATENATE("(", opt3_number_of_lives_renewal, " lives)") -> (800 lives) | G11: =CONCATENATE("(", opt3_number_of_lives_renewal, " lives)") -> (800 lives) | J11: =CONCATENATE("(", opt3_number_of_lives_renewal, " lives)") -> (800 lives)
B12: =Inputs!B31 -> IV. ESCP with 0% Co-Pay (SI : 5 L) | D12: =Inputs!I31 -> 50,00,000 | E12: =D12/opt4_number_of_lives_renewal -> #VALUE! | G12: =Inputs!J31 -> 50,00,000 | H12: =G12/opt4_number_of_lives_renewal -> #VALUE! | J12: =Inputs!K31 -> 50,00,000 | K12: =J12/opt4_number_of_lives_renewal -> #VALUE! | M12: - | N12: - | P12: =Inputs!B31 -> IV. ESCP with 0% Co-Pay (SI : 5 L) | R12: =Inputs!D31 -> 6 | S12: =Inputs!E31 -> 800
D13: =CONCATENATE("(", opt4_number_of_lives_renewal, " lives)") -> (800 lives) | G13: =CONCATENATE("(", opt4_number_of_lives_renewal, " lives)") -> (800 lives) | J13: =CONCATENATE("(", opt4_number_of_lives_renewal, " lives)") -> (800 lives)
B14: =Inputs!B33 -> V. ESCP with 0% Co-Pay (SI : 5 L) | D14: =Inputs!I33 -> 60,00,000 | E14: =D14/opt5_number_of_lives_renewal -> #VALUE! | G14: =Inputs!J33 -> 60,00,000 | H14: =G14/opt5_number_of_lives_renewal -> #VALUE! | J14: =Inputs!K33 -> 60,00,000 | K14: =J14/opt5_number_of_lives_renewal -> #VALUE! | M14: - | N14: - | P14: =Inputs!B33 -> V. ESCP with 0% Co-Pay (SI : 5 L) | R14: =Inputs!D33 -> 6 | S14: =Inputs!E33 -> 800
D15: =CONCATENATE("(", opt5_number_of_lives_renewal, " lives)") -> (800 lives) | G15: =CONCATENATE("(", opt5_number_of_lives_renewal, " lives)") -> (800 lives) | J15: =CONCATENATE("(", opt5_number_of_lives_renewal, " lives)") -> (800 lives)
D18: Group Personal Accident Insurance
D19: Options for Renewal | M19: Previous Policy
D20: =Inputs!I43 -> Magma HDI (Basic Plan) - NEE Group | G20: =Inputs!J43 -> Magma HDI (Pro Plan) - NEE Group | J20: =Inputs!K43 -> Go Digit (Pro Plan) | M20: =Inputs!L43 -> IFFCO Tokio ( Pro Plan) | P20: Proposed Options | R20: No. of Employees (renewal) | T20: No. of Employees (expiring policy)
D21: Total Premium (₹) | E21: Premium per Mille | G21: Total Premium (₹) | H21: Premium per Mille | J21: Total Premium (₹) | K21: Premium per Mille | M21: Total Premium (₹) | N21: Premium per Mille
B22: =Inputs!B45 -> I. Expiring Terms (SI: 10 L) | D22: =Inputs!I45 -> 20,00,000 | E22: =D22/GPA_opt1_number_of_employees_renewal -> #VALUE! | G22: =Inputs!J45 -> 20,00,000 | H22: =G22/GPA_opt1_number_of_employees_renewal -> #VALUE! | J22: =Inputs!K45 -> 20,00,000 | K22: =J22/GPA_opt1_number_of_employees_renewal -> #VALUE! | M22: =Inputs!L45 -> 20,00,000 | N22: =M22/GPA_number_of_lives_expiring -> #VALUE! | P22: =Inputs!B45 -> I. Expiring Terms (SI: 10 L) | R22: =Inputs!D45 -> 30 | T22: =Inputs!F45 -> 20
D23: =CONCATENATE("(", GPA_opt1_number_of_employees_renewal, " employees)") -> (30 employees) | G23: =CONCATENATE("(", GPA_opt1_number_of_employees_renewal, " employees)") -> (30 employees) | J23: =CONCATENATE("(", GPA_opt1_number_of_employees_renewal, " employees)") -> (30 employees) | M23: =CONCATENATE("(", GPA_opt1_number_of_employees_expiring, " employees)") -> (20 employees)
B24: =Inputs!B47 -> II. SI: 25 L | D24: =Inputs!I47 -> 39,00,000 | E24: =D24/GPA_opt2_number_of_employees_renewal -> #VALUE! | G24: =Inputs!J47 -> 30,00,000 | H24: =G24/GPA_opt2_number_of_employees_renewal -> #VALUE! | J24: =Inputs!K47 -> 30,00,000 | K24: =J24/GPA_opt2_number_of_employees_renewal -> #VALUE! | M24: - | N24: - | P24: =Inputs!B47 -> II. SI: 25 L | R24: =Inputs!D47 -> 30 | T24: -
D25: =CONCATENATE("(", GPA_opt2_number_of_employees_renewal, " employees)") -> (30 employees) | G25: =CONCATENATE("(", GPA_opt2_number_of_employees_renewal, " employees)") -> (30 employees) | J25: =CONCATENATE("(", GPA_opt2_number_of_employees_renewal, " employees)") -> (30 employees)
D28: Group Term Life Insurance
D29: Options for Renewal | M29: Previous Policy
D30: =Inputs!I57 -> CALI (Exclusive) | G30: =Inputs!J57 -> CALI (Exclusive) | J30: =Inputs!K57 -> HDFC Life | M30: =Inputs!L57 -> Pramerica Life | P30: Proposed Options | R30: No. of Employees (renewal) | T30: No. of Employees (expiring policy)
D31: Total Premium (₹) | E31: Premium per Mille | G31: Total Premium (₹) | H31: Premium per Mille | J31: Total Premium (₹) | K31: Premium per Mille | M31: Total Premium (₹) | N31: Premium per Mille
B32: =Inputs!B59 -> I. Expiring Terms (SI: 10 L) | D32: =Inputs!I59 -> 25,00,000 | E32: =D32/GTLI_opt1_number_of_employees_renewal -> #VALUE! | G32: =Inputs!J59 -> 20,00,000 | H32: =G32/GTLI_opt1_number_of_employees_renewal -> #VALUE! | J32: =Inputs!K59 -> 20,00,000 | K32: =J32/GTLI_opt1_number_of_employees_renewal -> #VALUE! | M32: =Inputs!L59 -> 20,00,000 | N32: =M32/GTLI_number_of_employees_expiring -> #VALUE! | P32: =B32 -> I. Expiring Terms (SI: 10 L) | R32: =Inputs!D59 -> 300 | T32: =Inputs!F59 -> 150
D33: =CONCATENATE("(", GTLI_opt1_number_of_employees_renewal, " employees)") -> (300 employees) | G33: =CONCATENATE("(", GTLI_opt1_number_of_employees_renewal, " employees)") -> (300 employees) | J33: =CONCATENATE("(", GTLI_opt1_number_of_employees_renewal, " employees)") -> (300 employees) | M33: {=CONCATENATE("(", GTLI_number_of_employees_expiring, " employees)")} -> (150 employees)
B34: =Inputs!B61 -> II. SI: 25 L | D34: =Inputs!I61 -> 35,00,000 | E34: =D34/GTLI_opt2_number_of_employees_renewal -> #VALUE! | G34: =Inputs!J61 -> 30,00,000 | H34: =G34/GTLI_opt2_number_of_employees_renewal -> #VALUE! | J34: =Inputs!K61 -> 30,00,000 | K34: =J34/GTLI_opt2_number_of_employees_renewal -> #VALUE! | M34: - | N34: - | P34: =B34 -> II. SI: 25 L | R34: =Inputs!D61 -> 300 | T34: -
D35: =CONCATENATE("(", GTLI_opt1_number_of_employees_renewal, " employees)") -> (300 employees) | G35: =CONCATENATE("(", GTLI_opt2_number_of_employees_renewal, " employees)") -> (300 employees) | J35: =CONCATENATE("(", GTLI_opt2_number_of_employees_renewal, " employees)") -> (300 employees)

Sheet Policy & Technical Features - o
B3: Policy Features – Group Health Insurance
L5: Incumbent Insurer | Z5: =L5 -> Incumbent Insurer
A6: Logo | B6: Features | C6: =SUBSTITUTE(B6," ","") -> Features | D6: Benefits | F6: =Inputs!B14 -> Manipal Cigna Standard Rater | H6: =Inputs!C14 -> SBI General | J6: =Inputs!D14 -> Manipal Cigna | L6: =Inputs!E14 -> IFFCO Tokio | O6: Plan Type:- | Q6: =B6 -> Features | R6: =D6 -> Benefits | T6: =F6 -> Manipal Cigna Standard Rater | V6: =H6 -> SBI General | X6: =J6 -> Manipal Cigna | Z6: =L6 -> IFFCO Tokio
B7: Family Definition | D7: Plan Type | F7: Employee, Spouse, and Children | H7: Employee, Spouse, and Children | J7: Employee, Spouse, and Children | L7: Employee, Spouse, and Children | O7: Employee only | Q7: =B7 -> Family Definition | R7: =D7 -> Plan Type | T7: =F7 -> Employee, Spouse, and Children | V7: =H7 -> Employee, Spouse, and Children | X7: =J7 -> Employee, Spouse, and Children | Z7: =L7 -> Employee, Spouse, and Children
C8: =SUBSTITUTE(B7," ","") -> FamilyDefinition | D8: Children - upto 25 yrs of age | F8: =INDEX('GHI DB'!$C$4:$BS$21,MATCH('Policy & Technical Features - o'!F$6,'GHI DB'!$A$4:$A$21,0),MATCH('Policy & Technical Features - o'!$D8,'GHI DB'!$C$3:$BS$3,0)) -> #N/A | H8: =INDEX('GHI DB'!$C$4:$BS$21,MATCH('Policy & Technical Features - o'!H$6,'GHI DB'!$A$4:$A$21,0),MATCH('Policy & Technical Features - o'!$D8,'GHI DB'!$C$3:$BS$3,0)) -> #N/A | J8: =INDEX('GHI DB'!$C$4:$BS$21,MATCH('Policy & Technical Features - o'!J$6,'GHI DB'!$A$4:$A$21,0),MATCH('Policy & Technical Features - o'!$D8,'GHI DB'!$C$3:$BS$3,0)) -> 2 | L8: =INDEX('GHI DB'!$C$4:$BS$21,MATCH('Policy & Technical Features - o'!L$6,'GHI DB'!$A$4:$A$21,0),MATCH('Policy & Technical Features - o'!$D8,'GHI DB'!$C$3:$BS$3,0)) -> 2 | O8: Employee, Spouse, and Children | R8: =D8 -> Children - upto 25 yrs of age | T8: =F8 -> #N/A | V8: =H8 -> #N/A | X8: =J8 -> 2 | Z8: =L8 -> 2
C9: =SUBSTITUTE(B7," ","") -> FamilyDefinition | D9: 2 Parents/PIL - upto 80 yrs of age | F9: =INDEX('GHI DB'!$C$4:$BS$21,MATCH('Policy & Technical Features - o'!F$6,'GHI DB'!$A$4:$A$21,0),MATCH('Policy & Technical Features - o'!$D9,'GHI DB'!$C$3:$BS$3,0)) -> #N/A | H9: =INDEX('GHI DB'!$C$4:$BS$21,MATCH('Policy & Technical Features - o'!H$6,'GHI DB'!$A$4:$A$21,0),MATCH('Policy & Technical Features - o'!$D9,'GHI DB'!$C$3:$BS$3,0)) -> #N/A | J9: =INDEX('GHI DB'!$C$4:$BS$21,MATCH('Policy & Technical Features - o'!J$6,'GHI DB'!$A$4:$A$21,0),MATCH('Policy & Technical Features - o'!$D9,'GHI DB'!$C$3:$BS$3,0)) -> ✔ | L9: =INDEX('GHI DB'!$C$4:$BS$21,MATCH('Policy & Technical Features - o'!L$6,'GHI DB'!$A$4:$A$21,0),MATCH('Policy & Technical Features - o'!$D9,'GHI DB'!$C$3:$BS$3,0)) -> ✔ | O9: Employee, Spouse, Children, and Parents/Parents-in-law | R9: =D9 -> 2 Parents/PIL - upto 80 yrs of age | T9: =F9 -> #N/A | V9: =H9 -> #N/A | X9: =J9 -> ✔ | Z9: =L9 -> ✔
B10: Room Rent Restriction | C10: =SUBSTITUTE(B10," ","") -> RoomRentRestriction | D10: Normal -Single Pvt. AC ICU - No Capping (per day) | F10: =INDEX('GHI DB'!$C$4:$BS$21,MATCH('Policy & Technical Features - o'!F$6,'GHI DB'!$A$4:$A$21,0),MATCH('Policy & Technical Features - o'!$D10,'GHI DB'!$C$3:$BS$3,0)) -> #N/A | H10: =INDEX('GHI DB'!$C$4:$BS$21,MATCH('Policy & Technical Features - o'!H$6,'GHI DB'!$A$4:$A$21,0),MATCH('Policy & Technical Features - o'!$D10,'GHI DB'!$C$3:$BS$3,0)) -> #N/A | J10: =INDEX('GHI DB'!$C$4:$BS$21,MATCH('Policy & Technical Features - o'!J$6,'GHI DB'!$A$4:$A$21,0),MATCH('Policy & Technical Features - o'!$D10,'GHI DB'!$C$3:$BS$3,0)) -> #N/A | L10: =INDEX('GHI DB'!$C$4:$BS$21,MATCH('Policy & Technical Features - o'!L$6,'GHI DB'!$A$4:$A$21,0),MATCH('Policy & Technical Features - o'!$D10,'GHI DB'!$C$3:$BS$3,0)) -> #N/A | Q10: =B10 -> Room Rent Restriction | R10: =D10 -> Normal -Single Pvt. AC ICU - No Capping (per day) | T10: =F10 -> #N/A | V10: =H10 -> #N/A | X10: =J10 -> #N/A | Z10: =L10 -> #N/A
B11: Maternity Cover | C11: =SUBSTITUTE(B11," ","") -> MaternityCover | D11: Normal - Rs. 50k C Section - Rs. 50K | F11: =INDEX('GHI DB'!$C$4:$BS$21,MATCH('Policy & Technical Features - o'!F$6,'GHI DB'!$A$4:$A$21,0),MATCH('Policy & Technical Features - o'!$D11,'GHI DB'!$C$3:$BS$3,0)) -> #N/A | H11: =INDEX('GHI DB'!$C$4:$BS$21,MATCH('Policy & Technical Features - o'!H$6,'GHI DB'!$A$4:$A$21,0),MATCH('Policy & Technical Features - o'!$D11,'GHI DB'!$C$3:$BS$3,0)) -> #N/A | J11: =INDEX('GHI DB'!$C$4:$BS$21,MATCH('Policy & Technical Features - o'!J$6,'GHI DB'!$A$4:$A$21,0),MATCH('Policy & Technical Features - o'!$D11,'GHI DB'!$C$3:$BS$3,0)) -> ✔ | L11: =INDEX('GHI DB'!$C$4:$BS$21,MATCH('Policy & Technical Features - o'!L$6,'GHI DB'!$A$4:$A$21,0),MATCH('Policy & Technical Features - o'!$D11,'GHI DB'!$C$3:$BS$3,0)) -> ✔ | Q11: =B11 -> Maternity Cover | R11: =D11 -> Normal - Rs. 50k C Section - Rs. 50K | T11: =F11 -> #N/A | V11: =H11 -> #N/A | X11: =J11 -> ✔ | Z11: =L11 -> ✔
B12: Co Pay | C12: =SUBSTITUTE(B12," ","") -> CoPay | D12: 0% Co-Pay | F12: =INDEX('GHI DB'!$C$4:$BS$21,MATCH('Policy & Technical Features - o'!F$6,'GHI DB'!$A$4:$A$21,0),MATCH('Policy & Technical Features - o'!$D12,'GHI DB'!$C$3:$BS$3,0)) -> #N/A | H12: =INDEX('GHI DB'!$C$4:$BS$21,MATCH('Policy & Technical Features - o'!H$6,'GHI DB'!$A$4:$A$21,0),MATCH('Policy & Technical Features - o'!$D12,'GHI DB'!$C$3:$BS$3,0)) -> #N/A | J12: =INDEX('GHI DB'!$C$4:$BS$21,MATCH('Policy & Technical Features - o'!J$6,'GHI DB'!$A$4:$A$21,0),MATCH('Policy & Technical Features - o'!$D12,'GHI DB'!$C$3:$BS$3,0)) -> ✔ | L12: =INDEX('GHI DB'!$C$4:$BS$21,MATCH('Policy & Technical Features - o'!L$6,'GHI DB'!$A$4:$A$21,0),MATCH('Policy & Technical Features - o'!$D12,'GHI DB'!$C$3:$BS$3,0)) -> ✔ | Q12: =B12 -> Co Pay | R12: =D12 -> 0% Co-Pay | T12: =F12 -> #N/A | V12: =H12 -> #N/A | X12: =J12 -> ✔ | Z12: =L12 -> ✔
B13: Psychiatric Illness | C13: =SUBSTITUTE(B13," ","") -> PsychiatricIllness | D13: Hospitalization > 24 hours | F13: =INDEX('GHI DB'!$C$4:$BS$21,MATCH('Policy & Technical Features - o'!F$6,'GHI DB'!$A$4:$A$21,0),MATCH('Policy & Technical Features - o'!$D13,'GHI DB'!$C$3:$BS$3,0)) -> #N/A | H13: =INDEX('GHI DB'!$C$4:$BS$21,MATCH('Policy & Technical Features - o'!H$6,'GHI DB'!$A$4:$A$21,0),MATCH('Policy & Technical Features - o'!$D13,'GHI DB'!$C$3:$BS$3,0)) -> #N/A | J13: =INDEX('GHI DB'!$C$4:$BS$21,MATCH('Policy & Technical Features - o'!J$6,'GHI DB'!$A$4:$A$21,0),MATCH('Policy & Technical Features - o'!$D13,'GHI DB'!$C$3:$BS$3,0)) -> ✔ | L13: =INDEX('GHI DB'!$C$4:$BS$21,MATCH('Policy & Technical Features - o'!L$6,'GHI DB'!$A$4:$A$21,0),MATCH('Policy & Technical Features - o'!$D13,'GHI DB'!$C$3:$BS$3,0)) -> ✔ | Q13: =B13 -> Psychiatric Illness | R13: =D13 -> Hospitalization > 24 hours | T13: =F13 -> #N/A | V13: =H13 -> #N/A | X13: =J13 -> ✔ | Z13: =L13 -> ✔
B14: Pre and Post Hospitalization Coverage | C14: =SUBSTITUTE(B14," ","") -> PreandPostHospitalizationCoverage | D14: 30/60 days (For in-patient Hospitalization) | F14: =INDEX('GHI DB'!$C$4:$BS$21,MATCH('Policy & Technical Features - o'!F$6,'GHI DB'!$A$4:$A$21,0),MATCH('Policy & Technical Features - o'!$D14,'GHI DB'!$C$3:$BS$3,0)) -> #N/A | H14: =INDEX('GHI DB'!$C$4:$BS$21,MATCH('Policy & Technical Features - o'!H$6,'GHI DB'!$A$4:$A$21,0),MATCH('Policy & Technical Features - o'!$D14,'GHI DB'!$C$3:$BS$3,0)) -> #N/A | J14: =INDEX('GHI DB'!$C$4:$BS$21,MATCH('Policy & Technical Features - o'!J$6,'GHI DB'!$A$4:$A$21,0),MATCH('Policy & Technical Features - o'!$D14,'GHI DB'!$C$3:$BS$3,0)) -> #N/A | L14: =INDEX('GHI DB'!$C$4:$BS$21,MATCH('Policy & Technical Features - o'!L$6,'GHI DB'!$A$4:$A$21,0),MATCH('Policy & Technical Features - o'!$D14,'GHI DB'!$C$3:$BS$3,0)) -> #N/A | Q14: =B14 -> Pre and Post Hospitalization Coverage | R14: =D14 -> 30/60 days (For in-patient Hospitalization) | T14: =F14 -> #N/A | V14: =H14 -> #N/A | X14: =J14 -> #N/A | Z14: =L14 -> #N/A
B15: Mid term Addition of Dependents | C15: =SUBSTITUTE(B15," ","") -> MidtermAdditionofDependents | D15: Hospitallization > 24 hours in Govt Approved Hospitals | F15: =INDEX('GHI DB'!$C$4:$BS$21,MATCH('Policy & Technical Features - o'!F$6,'GHI DB'!$A$4:$A$21,0),MATCH('Policy & Technical Features - o'!$D15,'GHI DB'!$C$3:$BS$3,0)) -> #N/A | H15: =INDEX('GHI DB'!$C$4:$BS$21,MATCH('Policy & Technical Features - o'!H$6,'GHI DB'!$A$4:$A$21,0),MATCH('Policy & Technical Features - o'!$D15,'GHI DB'!$C$3:$BS$3,0)) -> #N/A | J15: =INDEX('GHI DB'!$C$4:$BS$21,MATCH('Policy & Technical Features - o'!J$6,'GHI DB'!$A$4:$A$21,0),MATCH('Policy & Technical Features - o'!$D15,'GHI DB'!$C$3:$BS$3,0)) -> Not Covered | L15: =INDEX('GHI DB'!$C$4:$BS$21,MATCH('Policy & Technical Features - o'!L$6,'GHI DB'!$A$4:$A$21,0),MATCH('Policy & Technical Features - o'!$D15,'GHI DB'!$C$3:$BS$3,0)) -> ✔ | Q15: =B15 -> Mid term Addition of Dependents | R15: =D15 -> Hospitallization > 24 hours in Govt Approved Hospitals | T15: =F15 -> #N/A | V15: =H15 -> #N/A | X15: =J15 -> Not Covered | Z15: =L15 -> ✔
B16: Emergency Ambulance | C16: =SUBSTITUTE(B16," ","") -> EmergencyAmbulance | D16: Coverage per event | F16: =INDEX('GHI DB'!$C$4:$BS$21,MATCH('Policy & Technical Features - o'!F$6,'GHI DB'!$A$4:$A$21,0),MATCH('Policy & Technical Features - o'!$D16,'GHI DB'!$C$3:$BS$3,0)) -> #N/A | H16: =INDEX('GHI DB'!$C$4:$BS$21,MATCH('Policy & Technical Features - o'!H$6,'GHI DB'!$A$4:$A$21,0),MATCH('Policy & Technical Features - o'!$D16,'GHI DB'!$C$3:$BS$3,0)) -> #N/A | J16: =INDEX('GHI DB'!$C$4:$BS$21,MATCH('Policy & Technical Features - o'!J$6,'GHI DB'!$A$4:$A$21,0),MATCH('Policy & Technical Features - o'!$D16,'GHI DB'!$C$3:$BS$3,0)) -> Upto Rs. 2.5k | L16: =INDEX('GHI DB'!$C$4:$BS$21,MATCH('Policy & Technical Features - o'!L$6,'GHI DB'!$A$4:$A$21,0),MATCH('Policy & Technical Features - o'!$D16,'GHI DB'!$C$3:$BS$3,0)) -> Upto Rs. 1k | Q16: =B16 -> Emergency Ambulance | R16: =D16 -> Coverage per event | T16: =F16 -> #N/A | V16: =H16 -> #N/A | X16: =J16 -> Upto Rs. 2.5k | Z16: =L16 -> Upto Rs. 1k
B17: Emergency Ambulance | C17: =SUBSTITUTE(B17," ","") -> EmergencyAmbulance | D17: Coverage per event | F17: =INDEX('GHI DB'!$C$4:$BS$21,MATCH('Policy & Technical Features - o'!F$6,'GHI DB'!$A$4:$A$21,0),MATCH('Policy & Technical Features - o'!$D17,'GHI DB'!$C$3:$BS$3,0)) -> #N/A | H17: =INDEX('GHI DB'!$C$4:$BS$21,MATCH('Policy & Technical Features - o'!H$6,'GHI DB'!$A$4:$A$21,0),MATCH('Policy & Technical Features - o'!$D17,'GHI DB'!$C$3:$BS$3,0)) -> #N/A | J17: =INDEX('GHI DB'!$C$4:$BS$21,MATCH('Policy & Technical Features - o'!J$6,'GHI DB'!$A$4:$A$21,0),MATCH('Policy & Technical Features - o'!$D17,'GHI DB'!$C$3:$BS$3,0)) -> Upto Rs. 2.5k | L17: =INDEX('GHI DB'!$C$4:$BS$21,MATCH('Policy & Technical Features - o'!L$6,'GHI DB'!$A$4:$A$21,0),MATCH('Policy & Technical Features - o'!$D17,'GHI DB'!$C$3:$BS$3,0)) -> Upto Rs. 1k | Q17: =B17 -> Emergency Ambulance | R17: =D17 -> Coverage per event | T17: =F17 -> #N/A | V17: =H17 -> #N/A | X17: =J17 -> Upto Rs. 2.5k | Z17: =L17 -> Upto Rs. 1k
B18: Inpatient Hospitalization | C18: =SUBSTITUTE(B18," ","") -> InpatientHospitalization | D18: Hospitallization > 24 hours in Govt Approved Hospitals | F18: =INDEX('GHI DB'!$C$4:$BS$21,MATCH('Policy & Technical Features - o'!F$6,'GHI DB'!$A$4:$A$21,0),MATCH('Policy & Technical Features - o'!$D18,'GHI DB'!$C$3:$BS$3,0)) -> #N/A | H18: =INDEX('GHI DB'!$C$4:$BS$21,MATCH('Policy & Technical Features - o'!H$6,'GHI DB'!$A$4:$A$21,0),MATCH('Policy & Technical Features - o'!$D18,'GHI DB'!$C$3:$BS$3,0)) -> #N/A | J18: =INDEX('GHI DB'!$C$4:$BS$21,MATCH('Policy & Technical Features - o'!J$6,'GHI DB'!$A$4:$A$21,0),MATCH('Policy & Technical Features - o'!$D18,'GHI DB'!$C$3:$BS$3,0)) -> Not Covered | L18: =INDEX('GHI DB'!$C$4:$BS$21,MATCH('Policy & Technical Features - o'!L$6,'GHI DB'!$A$4:$A$21,0),MATCH('Policy & Technical Features - o'!$D18,'GHI DB'!$C$3:$BS$3,0)) -> ✔ | Q18: =B18 -> Inpatient Hospitalization | R18: =D18 -> Hospitallization > 24 hours in Govt Approved Hospitals | T18: =F18 -> #N/A | V18: =H18 -> #N/A | X18: =J18 -> Not Covered | Z18: =L18 -> ✔
B24: Know Your Insurer - Credentials
L26: Incumbent Insurer | Z26: =L26 -> Incumbent Insurer
A27: Logo | B27: Features | D27: Parameter | F27: =Inputs!B14 -> Manipal Cigna Standard Rater | H27: =Inputs!C14 -> SBI General | J27: =Inputs!D14 -> Manipal Cigna | L27: =Inputs!E14 -> IFFCO Tokio | Q27: =B27 -> Features | R27: =D27 -> Parameter | T27: =F27 -> Manipal Cigna Standard Rater | V27: =H27 -> SBI General | X27: =J27 -> Manipal Cigna | Z27: =L27 -> IFFCO Tokio
B28: Background and Credibility | C28: Background and Credibility | D28: Founding Year | F28: =INDEX('Technical DB (Health)'!$C$3:$Q$20,MATCH(F$27,'Technical DB (Health)'!$A$3:$A$20,0),MATCH($D28,'Technical DB (Health)'!$C$2:$Q$2,0)) -> #N/A | H28: =INDEX('Technical DB (Health)'!$C$3:$Q$20,MATCH(H$27,'Technical DB (Health)'!$A$3:$A$20,0),MATCH($D28,'Technical DB (Health)'!$C$2:$Q$2,0)) -> #N/A | J28: =INDEX('Technical DB (Health)'!$C$3:$Q$20,MATCH(J$27,'Technical DB (Health)'!$A$3:$A$20,0),MATCH($D28,'Technical DB (Health)'!$C$2:$Q$2,0)) -> 2014 | L28: =INDEX('Technical DB (Health)'!$C$3:$Q$20,MATCH(L$27,'Technical DB (Health)'!$A$3:$A$20,0),MATCH($D28,'Technical DB (Health)'!$C$2:$Q$2,0)) -> 2000 | Q28: =B28 -> Background and Credibility | R28: =D28 -> Founding Year | T28: =F28 -> #N/A | V28: =H28 -> #N/A | X28: =J28 -> 2014 | Z28: =L28 -> 2000
D29: Backed by | F29: =INDEX('Technical DB (Health)'!$C$3:$Q$20,MATCH(F$27,'Technical DB (Health)'!$A$3:$A$20,0),MATCH($D29,'Technical DB (Health)'!$C$2:$Q$2,0)) -> #N/A | H29: =INDEX('Technical DB (Health)'!$C$3:$Q$20,MATCH(H$27,'Technical DB (Health)'!$A$3:$A$20,0),MATCH($D29,'Technical DB (Health)'!$C$2:$Q$2,0)) -> #N/A | J29: =INDEX('Technical DB (Health)'!$C$3:$Q$20,MATCH(J$27,'Technical DB (Health)'!$A$3:$A$20,0),MATCH($D29,'Technical DB (Health)'!$C$2:$Q$2,0)) -> Manipal Group, Cigna Holdings | L29: =INDEX('Technical DB (Health)'!$C$3:$Q$20,MATCH(L$27,'Technical DB (Health)'!$A$3:$A$20,0),MATCH($D29,'Technical DB (Health)'!$C$2:$Q$2,0)) -> IFFCO India, Tokio Marine Insurance (Japan) | R29: =D29 -> Backed by | T29: =F29 -> #N/A | V29: =H29 -> #N/A | X29: =J29 -> Manipal Group, Cigna Holdings | Z29: =L29 -> IFFCO India, Tokio Marine Insurance (Japan)
B30: Market Presence | C30: Market Presence | D30: GHI Book Size (INR Crores) | F30: =INDEX('Technical DB (Health)'!$C$3:$Q$20,MATCH(F$27,'Technical DB (Health)'!$A$3:$A$20,0),MATCH($D30,'Technical DB (Health)'!$C$2:$Q$2,0)) -> #N/A | H30: =INDEX('Technical DB (Health)'!$C$3:$Q$20,MATCH(H$27,'Technical DB (Health)'!$A$3:$A$20,0),MATCH($D30,'Technical DB (Health)'!$C$2:$Q$2,0)) -> #N/A | J30: =INDEX('Technical DB (Health)'!$C$3:$Q$20,MATCH(J$27,'Technical DB (Health)'!$A$3:$A$20,0),MATCH($D30,'Technical DB (Health)'!$C$2:$Q$2,0)) -> #N/A | L30: =INDEX('Technical DB (Health)'!$C$3:$Q$20,MATCH(L$27,'Technical DB (Health)'!$A$3:$A$20,0),MATCH($D30,'Technical DB (Health)'!$C$2:$Q$2,0)) -> #N/A | Q30: =B30 -> Market Presence | R30: =D30 -> GHI Book Size (INR Crores) | T30: =F30 -> #N/A | V30: =H30 -> #N/A | X30: =J30 -> #N/A | Z30: =L30 -> #N/A
D31: GHI Growth Rate | F31: =INDEX('Technical DB (Health)'!$C$3:$Q$20,MATCH(F$27,'Technical DB (Health)'!$A$3:$A$20,0),MATCH($D31,'Technical DB (Health)'!$C$2:$Q$2,0)) -> #N/A | H31: =INDEX('Technical DB (Health)'!$C$3:$Q$20,MATCH(H$27,'Technical DB (Health)'!$A$3:$A$20,0),MATCH($D31,'Technical DB (Health)'!$C$2:$Q$2,0)) -> #N/A | J31: =INDEX('Technical DB (Health)'!$C$3:$Q$20,MATCH(J$27,'Technical DB (Health)'!$A$3:$A$20,0),MATCH($D31,'Technical DB (Health)'!$C$2:$Q$2,0)) -> #N/A | L31: =INDEX('Technical DB (Health)'!$C$3:$Q$20,MATCH(L$27,'Technical DB (Health)'!$A$3:$A$20,0),MATCH($D31,'Technical DB (Health)'!$C$2:$Q$2,0)) -> #N/A | R31: =D31 -> GHI Growth Rate | T31: =F31 -> #N/A | V31: =H31 -> #N/A | X31: =J31 -> #N/A | Z31: =L31 -> #N/A
B32: Financial Health | C32: Financial Health | D32: Solvency Ratio (IRDAI recommended: >1.5) | F32: =INDEX('Technical DB (Health)'!$C$3:$Q$20,MATCH(F$27,'Technical DB (Health)'!$A$3:$A$20,0),MATCH($D32,'Technical DB (Health)'!$C$2:$Q$2,0)) -> #N/A | H32: =INDEX('Technical DB (Health)'!$C$3:$Q$20,MATCH(H$27,'Technical DB (Health)'!$A$3:$A$20,0),MATCH($D32,'Technical DB (Health)'!$C$2:$Q$2,0)) -> #N/A | J32: =INDEX('Technical DB (Health)'!$C$3:$Q$20,MATCH(J$27,'Technical DB (Health)'!$A$3:$A$20,0),MATCH($D32,'Technical DB (Health)'!$C$2:$Q$2,0)) -> #N/A | L32: =INDEX('Technical DB (Health)'!$C$3:$Q$20,MATCH(L$27,'Technical DB (Health)'!$A$3:$A$20,0),MATCH($D32,'Technical DB (Health)'!$C$2:$Q$2,0)) -> #N/A | Q32: =B32 -> Financial Health | R32: =D32 -> Solvency Ratio (IRDAI recommended: >1.5) | T32: =F32 -> #N/A | V32: =H32 -> #N/A | X32: =J32 -> #N/A | Z32: =L32 -> #N/A
B33: Policy Administration | C33: Policy Administration | D33: Policy Issuance TAT | F33: =INDEX('Technical DB (Health)'!$C$3:$Q$20,MATCH(F$27,'Technical DB (Health)'!$A$3:$A$20,0),MATCH($D33,'Technical DB (Health)'!$C$2:$Q$2,0)) -> #N/A | H33: =INDEX('Technical DB (Health)'!$C$3:$Q$20,MATCH(H$27,'Technical DB (Health)'!$A$3:$A$20,0),MATCH($D33,'Technical DB (Health)'!$C$2:$Q$2,0)) -> #N/A | J33: =INDEX('Technical DB (Health)'!$C$3:$Q$20,MATCH(J$27,'Technical DB (Health)'!$A$3:$A$20,0),MATCH($D33,'Technical DB (Health)'!$C$2:$Q$2,0)) -> 10 to 20 days | L33: =INDEX('Technical DB (Health)'!$C$3:$Q$20,MATCH(L$27,'Technical DB (Health)'!$A$3:$A$20,0),MATCH($D33,'Technical DB (Health)'!$C$2:$Q$2,0)) -> 10 to 20 days | Q33: =B33 -> Policy Administration | R33: =D33 -> Policy Issuance TAT | T33: =F33 -> #N/A | V33: =H33 -> #N/A | X33: =J33 -> 10 to 20 days | Z33: =L33 -> 10 to 20 days
D34: Endorsement TAT | F34: =INDEX('Technical DB (Health)'!$C$3:$Q$20,MATCH(F$27,'Technical DB (Health)'!$A$3:$A$20,0),MATCH($D34,'Technical DB (Health)'!$C$2:$Q$2,0)) -> #N/A | H34: =INDEX('Technical DB (Health)'!$C$3:$Q$20,MATCH(H$27,'Technical DB (Health)'!$A$3:$A$20,0),MATCH($D34,'Technical DB (Health)'!$C$2:$Q$2,0)) -> #N/A | J34: =INDEX('Technical DB (Health)'!$C$3:$Q$20,MATCH(J$27,'Technical DB (Health)'!$A$3:$A$20,0),MATCH($D34,'Technical DB (Health)'!$C$2:$Q$2,0)) -> 3 to 5 days | L34: =INDEX('Technical DB (Health)'!$C$3:$Q$20,MATCH(L$27,'Technical DB (Health)'!$A$3:$A$20,0),MATCH($D34,'Technical DB (Health)'!$C$2:$Q$2,0)) -> 5 to 10 days | R34: =D34 -> Endorsement TAT | T34: =F34 -> #N/A | V34: =H34 -> #N/A | X34: =J34 -> 3 to 5 days | Z34: =L34 -> 5 to 10 days
B35: Claims Summary | C35: Claims Summary | D35: Cashless Network | F35: =INDEX('Technical DB (Health)'!$C$3:$Q$20,MATCH(F$27,'Technical DB (Health)'!$A$3:$A$20,0),MATCH($D35,'Technical DB (Health)'!$C$2:$Q$2,0)) -> #N/A | H35: =INDEX('Technical DB (Health)'!$C$3:$Q$20,MATCH(H$27,'Technical DB (Health)'!$A$3:$A$20,0),MATCH($D35,'Technical DB (Health)'!$C$2:$Q$2,0)) -> #N/A | J35: =INDEX('Technical DB (Health)'!$C$3:$Q$20,MATCH(J$27,'Technical DB (Health)'!$A$3:$A$20,0),MATCH($D35,'Technical DB (Health)'!$C$2:$Q$2,0)) -> 8,500+ | L35: =INDEX('Technical DB (Health)'!$C$3:$Q$20,MATCH(L$27,'Technical DB (Health)'!$A$3:$A$20,0),MATCH($D35,'Technical DB (Health)'!$C$2:$Q$2,0)) -> 7,000+ | Q35: =B35 -> Claims Summary | R35: =D35 -> Cashless Network | T35: =F35 -> #N/A | V35: =H35 -> #N/A | X35: =J35 -> 8,500+ | Z35: =L35 -> 7,000+
D36: Claim Settlement Ratio | F36: =INDEX('Technical DB (Health)'!$C$3:$Q$20,MATCH(F$27,'Technical DB (Health)'!$A$3:$A$20,0),MATCH($D36,'Technical DB (Health)'!$C$2:$Q$2,0)) -> #N/A | H36: =INDEX('Technical DB (Health)'!$C$3:$Q$20,MATCH(H$27,'Technical DB (Health)'!$A$3:$A$20,0),MATCH($D36,'Technical DB (Health)'!$C$2:$Q$2,0)) -> #N/A | J36: =INDEX('Technical DB (Health)'!$C$3:$Q$20,MATCH(J$27,'Technical DB (Health)'!$A$3:$A$20,0),MATCH($D36,'Technical DB (Health)'!$C$2:$Q$2,0)) -> 0.98 | L36: =INDEX('Technical DB (Health)'!$C$3:$Q$20,MATCH(L$27,'Technical DB (Health)'!$A$3:$A$20,0),MATCH($D36,'Technical DB (Health)'!$C$2:$Q$2,0)) -> 0.98 | R36: =D36 -> Claim Settlement Ratio | T36: =F36 -> #N/A | V36: =H36 -> #N/A | X36: =J36 -> 0.98 | Z36: =L36 -> 0.98
D37: Cashless TAT | F37: =INDEX('Technical DB (Health)'!$C$3:$Q$20,MATCH(F$27,'Technical DB (Health)'!$A$3:$A$20,0),MATCH($D37,'Technical DB (Health)'!$C$2:$Q$2,0)) -> #N/A | H37: =INDEX('Technical DB (Health)'!$C$3:$Q$20,MATCH(H$27,'Technical DB (Health)'!$A$3:$A$20,0),MATCH($D37,'Technical DB (Health)'!$C$2:$Q$2,0)) -> #N/A | J37: =INDEX('Technical DB (Health)'!$C$3:$Q$20,MATCH(J$27,'Technical DB (Health)'!$A$3:$A$20,0),MATCH($D37,'Technical DB (Health)'!$C$2:$Q$2,0)) -> 2 to 4 hours | L37: =INDEX('Technical DB (Health)'!$C$3:$Q$20,MATCH(L$27,'Technical DB (Health)'!$A$3:$A$20,0),MATCH($D37,'Technical DB (Health)'!$C$2:$Q$2,0)) -> 2 to 4 hours | R37: =D37 -> Cashless TAT | T37: =F37 -> #N/A | V37: =H37 -> #N/A | X37: =J37 -> 2 to 4 hours | Z37: =L37 -> 2 to 4 hours
D38: Reimbursement TAT | F38: =INDEX('Technical DB (Health)'!$C$3:$Q$20,MATCH(F$27,'Technical DB (Health)'!$A$3:$A$20,0),MATCH($D38,'Technical DB (Health)'!$C$2:$Q$2,0)) -> #N/A | H38: =INDEX('Technical DB (Health)'!$C$3:$Q$20,MATCH(H$27,'Technical DB (Health)'!$A$3:$A$20,0),MATCH($D38,'Technical DB (Health)'!$C$2:$Q$2,0)) -> #N/A | J38: =INDEX('Technical DB (Health)'!$C$3:$Q$20,MATCH(J$27,'Technical DB (Health)'!$A$3:$A$20,0),MATCH($D38,'Technical DB (Health)'!$C$2:$Q$2,0)) -> 15 to 30 days | L38: =INDEX('Technical DB (Health)'!$C$3:$Q$20,MATCH(L$27,'Technical DB (Health)'!$A$3:$A$20,0),MATCH($D38,'Technical DB (Health)'!$C$2:$Q$2,0)) -> 15 to 30 days | R38: =D38 -> Reimbursement TAT | T38: =F38 -> #N/A | V38: =H38 -> #N/A | X38: =J38 -> 15 to 30 days | Z38: =L38 -> 15 to 30 days
D39: % of claims settled in 3 months | F39: =INDEX('Technical DB (Health)'!$C$3:$Q$20,MATCH(F$27,'Technical DB (Health)'!$A$3:$A$20,0),MATCH($D39,'Technical DB (Health)'!$C$2:$Q$2,0)) -> #N/A | H39: =INDEX('Technical DB (Health)'!$C$3:$Q$20,MATCH(H$27,'Technical DB (Health)'!$A$3:$A$20,0),MATCH($D39,'Technical DB (Health)'!$C$2:$Q$2,0)) -> #N/A | J39: =INDEX('Technical DB (Health)'!$C$3:$Q$20,MATCH(J$27,'Technical DB (Health)'!$A$3:$A$20,0),MATCH($D39,'Technical DB (Health)'!$C$2:$Q$2,0)) -> 0.999 | L39: =INDEX('Technical DB (Health)'!$C$3:$Q$20,MATCH(L$27,'Technical DB (Health)'!$A$3:$A$20,0),MATCH($D39,'Technical DB (Health)'!$C$2:$Q$2,0)) -> 0.8989 | R39: =D39 -> % of claims settled in 3 months | T39: =F39 -> #N/A | V39: =H39 -> #N/A | X39: =J39 -> 0.999 | Z39: =L39 -> 0.8989
D40: Reimbursement Mode (Paperless/Paper) | F40: =INDEX('Technical DB (Health)'!$C$3:$Q$20,MATCH(F$27,'Technical DB (Health)'!$A$3:$A$20,0),MATCH($D40,'Technical DB (Health)'!$C$2:$Q$2,0)) -> #N/A | H40: =INDEX('Technical DB (Health)'!$C$3:$Q$20,MATCH(H$27,'Technical DB (Health)'!$A$3:$A$20,0),MATCH($D40,'Technical DB (Health)'!$C$2:$Q$2,0)) -> #N/A | J40: =INDEX('Technical DB (Health)'!$C$3:$Q$20,MATCH(J$27,'Technical DB (Health)'!$A$3:$A$20,0),MATCH($D40,'Technical DB (Health)'!$C$2:$Q$2,0)) -> Paperless | L40: =INDEX('Technical DB (Health)'!$C$3:$Q$20,MATCH(L$27,'Technical DB (Health)'!$A$3:$A$20,0),MATCH($D40,'Technical DB (Health)'!$C$2:$Q$2,0)) -> Paper-based | R40: =D40 -> Reimbursement Mode (Paperless/Paper) | T40: =F40 -> #N/A | V40: =H40 -> #N/A | X40: =J40 -> Paperless | Z40: =L40 -> Paper-based
D41: TPA (in-house or External) | F41: =INDEX('Technical DB (Health)'!$C$3:$Q$20,MATCH(F$27,'Technical DB (Health)'!$A$3:$A$20,0),MATCH($D41,'Technical DB (Health)'!$C$2:$Q$2,0)) -> #N/A | H41: =INDEX('Technical DB (Health)'!$C$3:$Q$20,MATCH(H$27,'Technical DB (Health)'!$A$3:$A$20,0),MATCH($D41,'Technical DB (Health)'!$C$2:$Q$2,0)) -> #N/A | J41: =INDEX('Technical DB (Health)'!$C$3:$Q$20,MATCH(J$27,'Technical DB (Health)'!$A$3:$A$20,0),MATCH($D41,'Technical DB (Health)'!$C$2:$Q$2,0)) -> In-house External Option available | L41: =INDEX('Technical DB (Health)'!$C$3:$Q$20,MATCH(L$27,'Technical DB (Health)'!$A$3:$A$20,0),MATCH($D41,'Technical DB (Health)'!$C$2:$Q$2,0)) -> In-house External Option available | R41: =D41 -> TPA (in-house or External) | T41: =F41 -> #N/A | V41: =H41 -> #N/A | X41: =J41 -> In-house External Option available | Z41: =L41 -> In-house External Option available
D44: ='High Level Quotes - Slide 1'!P2 -> File Path of Proposal Deck
B45: =Inputs!B9 -> C:\Users\shali\Downloads\ABCD\Healthysure Proposal Deck.pptx

Sheet Policy & Technical Features
B2: =Inputs!B9 -> C:\Users\shali\Downloads\ABCD\Healthysure Proposal Deck.pptx
B4: Policy Features – Group Health Insurance
L6: Incumbent Insurer | Z6: =L6 -> Incumbent Insurer
A7: Logo | B7: Features | C7: =SUBSTITUTE(B7," ","") -> Features | D7: Benefits | F7: =Inputs!B14 -> Manipal Cigna Standard Rater | H7: =Inputs!C14 -> SBI General | J7: =Inputs!D14 -> Manipal Cigna | L7: =Inputs!E14 -> IFFCO Tokio | O7: Plan Type:- | Q7: =B7 -> Features | R7: =D7 -> Benefits | T7: =F7 -> Manipal Cigna Standard Rater | V7: =H7 -> SBI General | X7: =J7 -> Manipal Cigna | Z7: =L7 -> IFFCO Tokio
B8: Family Definition | D8: Plan Type | F8: Employee, Spouse, and Children | H8: Employee, Spouse, and Children | J8: Employee, Spouse, and Children | L8: Employee, Spouse, and Children | O8: Employee only | Q8: =B8 -> Family Definition | R8: =D8 -> Plan Type | T8: =F8 -> Employee, Spouse, and Children | V8: =H8 -> Employee, Spouse, and Children | X8: =J8 -> Employee, Spouse, and Children | Z8: =L8 -> Employee, Spouse, and Children
C9: =SUBSTITUTE(B8," ","") -> FamilyDefinition | D9: Children - upto 25 yrs of age | F9: =VLOOKUP(D9,'GHI Features (Option 1)'!$E$15:$J$60,3,0) -> 2 | H9: =VLOOKUP(D9,'GHI Features (Option 1)'!$E$15:$J$60,4,0) -> 4 | J9: =VLOOKUP(D9,'GHI Features (Option 1)'!$E$15:$J$60,5,0) -> 4 | L9: =VLOOKUP(D9,'GHI Features (Option 1)'!$E$15:$J$60,6,0) -> 4 | O9: Employee, Spouse, and Children | R9: =D9 -> Children - upto 25 yrs of age | T9: =F9 -> 2 | V9: =H9 -> 4 | X9: =J9 -> 4 | Z9: =L9 -> 4
C10: =SUBSTITUTE(B8," ","") -> FamilyDefinition | D10: 2 Parents/PIL - upto 80 yrs of age | F10: =VLOOKUP(D10,'GHI Features (Option 1)'!$E$15:$J$60,3,0) -> ✔ | H10: =VLOOKUP(D10,'GHI Features (Option 1)'!$E$15:$J$60,4,0) -> ✖ | J10: =VLOOKUP(D10,'GHI Features (Option 1)'!$E$15:$J$60,5,0) -> ✖ | L10: =VLOOKUP(D10,'GHI Features (Option 1)'!$E$15:$J$60,6,0) -> ✔ | O10: Employee, Spouse, Children, and Parents/Parents-in-law | R10: =D10 -> 2 Parents/PIL - upto 80 yrs of age | T10: =F10 -> ✔ | V10: =H10 -> ✖ | X10: =J10 -> ✖ | Z10: =L10 -> ✔
B11: Inpatient Hospitalization | C11: =SUBSTITUTE(B11," ","") -> InpatientHospitalization | D11: =VLOOKUP(B11,'GHI Features (Option 1)'!$C$15:$J$60,3,0) -> Hospitalization > 24 hours | F11: =VLOOKUP(D11,'GHI Features (Option 1)'!$E$15:$J$60,3,0) -> ✔ | H11: =VLOOKUP(D11,'GHI Features (Option 1)'!$E$15:$J$60,4,0) -> ✔ | J11: =VLOOKUP(D11,'GHI Features (Option 1)'!$E$15:$J$60,5,0) -> ✔ | L11: =VLOOKUP(D11,'GHI Features (Option 1)'!$E$15:$J$60,6,0) -> ✔ | Q11: =B11 -> Inpatient Hospitalization | R11: =D11 -> Hospitalization > 24 hours | T11: =F11 -> ✔ | V11: =H11 -> ✔ | X11: =J11 -> ✔ | Z11: =L11 -> ✔
B12: Pre and Post Natal Expenses | C12: =SUBSTITUTE(B12," ","") -> PreandPostNatalExpenses | D12: =VLOOKUP(B12,'GHI Features (Option 1)'!$C$15:$J$60,3,0) -> Covered within maternity limit | F12: =VLOOKUP(D12,'GHI Features (Option 1)'!$E$15:$J$60,3,0) -> ✖ | H12: =VLOOKUP(D12,'GHI Features (Option 1)'!$E$15:$J$60,4,0) -> ✖ | J12: =VLOOKUP(D12,'GHI Features (Option 1)'!$E$15:$J$60,5,0) -> ✔ | L12: =VLOOKUP(D12,'GHI Features (Option 1)'!$E$15:$J$60,6,0) -> ✖ | Q12: =B12 -> Pre and Post Natal Expenses | R12: =D12 -> Covered within maternity limit | T12: =F12 -> ✖ | V12: =H12 -> ✖ | X12: =J12 -> ✔ | Z12: =L12 -> ✖
B13: Corporate Buffer | C13: =SUBSTITUTE(B13," ","") -> CorporateBuffer | D13: =VLOOKUP(B13,'GHI Features (Option 1)'!$C$15:$J$60,3,0) -> Not Covered | F13: =VLOOKUP(D13,'GHI Features (Option 1)'!$E$15:$J$60,3,0) -> Not Covered | H13: =VLOOKUP(D13,'GHI Features (Option 1)'!$E$15:$J$60,4,0) -> Not Covered | J13: =VLOOKUP(D13,'GHI Features (Option 1)'!$E$15:$J$60,5,0) -> Not Covered | L13: =VLOOKUP(D13,'GHI Features (Option 1)'!$E$15:$J$60,6,0) -> Not Covered | Q13: =B13 -> Corporate Buffer | R13: =D13 -> Not Covered | T13: =F13 -> Not Covered | V13: =H13 -> Not Covered | X13: =J13 -> Not Covered | Z13: =L13 -> Not Covered
B14: Psychiatric Illness | C14: =SUBSTITUTE(B14," ","") -> PsychiatricIllness | D14: =VLOOKUP(B14,'GHI Features (Option 1)'!$C$15:$J$60,3,0) -> Hospitalization > 24 hours | F14: =VLOOKUP(D14,'GHI Features (Option 1)'!$E$15:$J$60,3,0) -> ✔ | H14: =VLOOKUP(D14,'GHI Features (Option 1)'!$E$15:$J$60,4,0) -> ✔ | J14: =VLOOKUP(D14,'GHI Features (Option 1)'!$E$15:$J$60,5,0) -> ✔ | L14: =VLOOKUP(D14,'GHI Features (Option 1)'!$E$15:$J$60,6,0) -> ✔ | Q14: =B14 -> Psychiatric Illness | R14: =D14 -> Hospitalization > 24 hours | T14: =F14 -> ✔ | V14: =H14 -> ✔ | X14: =J14 -> ✔ | Z14: =L14 -> ✔
B15: Pre and Post Hospitalization Coverage | C15: =SUBSTITUTE(B15," ","") -> PreandPostHospitalizationCoverage | D15: =VLOOKUP(B15,'GHI Features (Option 1)'!$C$15:$J$60,3,0) -> Covered | F15: =VLOOKUP(D15,'GHI Features (Option 1)'!$E$15:$J$60,3,0) -> 30/60 days | H15: =VLOOKUP(D15,'GHI Features (Option 1)'!$E$15:$J$60,4,0) -> 60/90 Days | J15: =VLOOKUP(D15,'GHI Features (Option 1)'!$E$15:$J$60,5,0) -> 60/90 Days | L15: =VLOOKUP(D15,'GHI Features (Option 1)'!$E$15:$J$60,6,0) -> 30/60 days | Q15: =B15 -> Pre and Post Hospitalization Coverage | R15: =D15 -> Covered | T15: =F15 -> 30/60 days | V15: =H15 -> 60/90 Days | X15: =J15 -> 60/90 Days | Z15: =L15 -> 30/60 days
B16: Maternity Cover | C16: =SUBSTITUTE(B16," ","") -> MaternityCover | D16: =VLOOKUP(B16,'GHI Features (Option 1)'!$C$15:$J$60,3,0) -> Normal - Rs. 50k C Section - Rs. 50K | F16: =VLOOKUP(D16,'GHI Features (Option 1)'!$E$15:$J$60,3,0) -> ✔ | H16: =VLOOKUP(D16,'GHI Features (Option 1)'!$E$15:$J$60,4,0) -> Optional -50k (with extra loading) | J16: =VLOOKUP(D16,'GHI Features (Option 1)'!$E$15:$J$60,5,0) -> Optional - 35K, 50K, 75K (with extra loading) | L16: =VLOOKUP(D16,'GHI Features (Option 1)'!$E$15:$J$60,6,0) -> ✔ | Q16: =B16 -> Maternity Cover | R16: =D16 -> Normal - Rs. 50k C Section - Rs. 50K | T16: =F16 -> ✔ | V16: =H16 -> Optional -50k (with extra loading) | X16: =J16 -> Optional - 35K, 50K, 75K (with extra loading) | Z16: =L16 -> ✔
B17: Emergency Ambulance | C17: =SUBSTITUTE(B17," ","") -> EmergencyAmbulance | D17: =VLOOKUP(B17,'GHI Features (Option 1)'!$C$15:$J$60,3,0) -> Within 25 min Pan-India | F17: =VLOOKUP(D17,'GHI Features (Option 1)'!$E$15:$J$60,3,0) -> ✔ | H17: =VLOOKUP(D17,'GHI Features (Option 1)'!$E$15:$J$60,4,0) -> ✔ | J17: =VLOOKUP(D17,'GHI Features (Option 1)'!$E$15:$J$60,5,0) -> ✔ | L17: =VLOOKUP(D17,'GHI Features (Option 1)'!$E$15:$J$60,6,0) -> ✔ | Q17: =B17 -> Emergency Ambulance | R17: =D17 -> Within 25 min Pan-India | T17: =F17 -> ✔ | V17: =H17 -> ✔ | X17: =J17 -> ✔ | Z17: =L17 -> ✔
B18: Co Pay | C18: =SUBSTITUTE(B18," ","") -> CoPay | D18: =VLOOKUP(B18,'GHI Features (Option 1)'!$C$15:$J$60,3,0) -> 25% Co-Pay | F18: =VLOOKUP(D18,'GHI Features (Option 1)'!$E$15:$J$60,3,0) -> ✖ | H18: =VLOOKUP(D18,'GHI Features (Option 1)'!$E$15:$J$60,4,0) -> ✖ | J18: =VLOOKUP(D18,'GHI Features (Option 1)'!$E$15:$J$60,5,0) -> ✔ | L18: =VLOOKUP(D18,'GHI Features (Option 1)'!$E$15:$J$60,6,0) -> ✔ | Q18: =B18 -> Co Pay | R18: =D18 -> 25% Co-Pay | T18: =F18 -> ✖ | V18: =H18 -> ✖ | X18: =J18 -> ✔ | Z18: =L18 -> ✔
B19: Pre and Post Hospitalization Coverage | C19: =SUBSTITUTE(B19," ","") -> PreandPostHospitalizationCoverage | D19: =VLOOKUP(B19,'GHI Features (Option 1)'!$C$15:$J$60,3,0) -> Covered | F19: =VLOOKUP(D19,'GHI Features (Option 1)'!$E$15:$J$60,3,0) -> 30/60 days | H19: =VLOOKUP(D19,'GHI Features (Option 1)'!$E$15:$J$60,4,0) -> 60/90 Days | J19: =VLOOKUP(D19,'GHI Features (Option 1)'!$E$15:$J$60,5,0) -> 60/90 Days | L19: =VLOOKUP(D19,'GHI Features (Option 1)'!$E$15:$J$60,6,0) -> 30/60 days | Q19: =B19 -> Pre and Post Hospitalization Coverage | R19: =D19 -> Covered | T19: =F19 -> 30/60 days | V19: =H19 -> 60/90 Days | X19: =J19 -> 60/90 Days | Z19: =L19 -> 30/60 days
B25: Know Your Insurer - Credentials
